Workbook
Name uHead: #REF!

Sheet 總投報率
A1: 年度 | C1: 投資損益 | D1: 交易金額 | E1: 存款均額 | F1: 交易成本 | G1: 投資收益率 交易金額計 | H1: 投資收益率 存款均額計 | I1: 累積收益 | J1: 累積收益率 交易金額計 | K1: 累積收益率 存款均額計
A2: 2019 | B2: 股票 | C2: ='19'!P31 -> 33817.65 | D2: ='19'!G31 -> 1457600 | E2: ='Family-帳戶紀錄_old'!O5 -> 820472.06 | F2: =SUM('19'!H31,'19'!L31:M31) -> 8416 | G2: =C2/D2 -> 0.023200912 | H2: =C2/E2 -> 0.041217308 | I2: =C2 -> 33817.65 | J2: =$I2/SUM(D$2:D2) -> 0.023200912 | K2: =$I2/SUM(E$2:E2) -> 0.041217308
A3: 2020 | B3: 股票 | C3: ='20'!P30 -> 76267 | D3: ='20'!G30 -> 1770540 | E3: ='Family-帳戶紀錄_old'!O112 -> 921589.9 | F3: =SUM('20'!H30,'20'!L30:M30) -> 10505 | G3: =C3/D3 -> 0.043075559 | H3: =C3/E3 -> 0.082755898 | I3: =I2+C3 -> 110084.65 | J3: =$I3/SUM(D$2:D3) -> 0.034101572 | K3: =$I3/SUM(E$2:E3) -> 0.063192155
A4: 2021 | B4: 股票 | C4: ='21'!P118 -> 71433.41 | D4: ='21'!G118 -> 8499700 | E4: ='Family-帳戶紀錄_old'!O198 -> 3939074 | F4: =SUM('21'!H118,'21'!L118:M118) -> 43290 | G4: =C4/D4 -> 0.0084042272 | H4: =C4/E4 -> 0.018134569 | I4: =I3+C4 -> 181518.06 | J4: =$I4/SUM(D$2:D4) -> 0.015477536 | K4: =$I4/SUM(E$2:E4) -> 0.031951015
A5: 2022 | B5: 股票 | C5: ='22'!P34 -> 272512.2 | D5: ='22'!G34 -> 1829800 | E5: ='Family-帳戶紀錄_old'!O458 -> 1815958.4 | F5: =SUM('22'!H34,'22'!L34:M34) -> 11343 | G5: =C5/D5 -> 0.14893005 | H5: =C5/E5 -> 0.15006522 | I5: =I4+C5 -> 454030.26 | J5: =$I5/SUM(D$2:D5) -> 0.033488886 | K5: =$I5/SUM(E$2:E5) -> 0.06056083
A6: 2023 | B6: 股票 | C6: ='23'!P27 -> 17288.6 | D6: ='23'!G27 -> 920690 | E6: ='Family-帳戶紀錄_old'!O573 -> 1222860.3 | F6: =SUM('23'!H27,'23'!L27:M27) -> 5013 | G6: =C6/D6 -> 0.018777873 | H6: =C6/E6 -> 0.014137837 | I6: =I5+C6 -> 471318.86 | J6: =$I6/SUM(D$2:D6) -> 0.032553399 | K6: =$I6/SUM(E$2:E6) -> 0.054050609
A7: 2024 | B7: 股票 | C7: ='24'!P44 -> 43577.76 | D7: ='24'!G44 -> 3861650 | E7: ='Family-帳戶紀錄_old'!O644 -> 2724282.7 | F7: =SUM('24'!H44,'24'!L44:M44) -> 4815 | G7: =C7/D7 -> 0.011284751 | H7: =C7/E7 -> 0.015996049 | I7: =I6+C7 -> 514896.62 | J7: =$I7/SUM(D$2:D7) -> 0.028075092 | K7: =$I7/SUM(E$2:E7) -> 0.044991781
A8: 2025 | B8: 股票 | C8: ='25'!P56+'25'!Q56 -> 22040.01 | D8: ='25'!G56 -> 3219840 | E8: ='Family-帳戶紀錄_old'!O644 -> 2724282.7 | F8: =SUM('25'!H56,'25'!L56:M56) -> 4442 | G8: =C8/D8 -> 0.0068450637 | H8: =C8/E8 -> 0.0080902066 | I8: =I7+C8 -> 536936.63 | J8: =$I8/SUM(D$2:D8) -> 0.024904504 | K8: =$I8/SUM(E$2:E8) -> 0.037896451
A9: 2026 | B9: 股票 | C9: ='2026'!P97+'2026'!Q97 -> 1257992.8 | D9: ='2026'!G97 -> 3265447.9 | E9: ='Family-帳戶紀錄_old'!O644 -> 2724282.7 | F9: =SUM('2026'!H97,'2026'!L97:M97) -> 5592 | G9: =C9/D9 -> 0.38524357 | H9: =C9/E9 -> 0.46177028 | I9: =I8+C9 -> 1794929.4 | J9: =$I9/SUM(D$2:D9) -> 0.07230252 | K9: =$I9/SUM(E$2:E9) -> 0.10625409
A10: 總計 | C10: =SUM(C2:C9) -> 1794929.4 | D10: =SUM(D2:D9) -> 24825268 | E10: =SUM(E2:E9) -> 16892803 | F10: =SUM(F2:F9) -> 93416 | G10: =C10/D10 -> 0.07230252 | H10: =C10/E10 -> 0.10625409

Sheet 2026
A1: 買進日期 | B1: 種類 | C1: 股票代號 | D1: 股票名稱 | E1: 股數 | F1: 買進價 | G1: 成交金額 | H1: 手續費 | I1: 賣出日期 | J1: 賣出價 | K1: 成交金額 | L1: 手續費 | M1: 交易稅 | N1: 證所稅 | O1: 參考現值 | P1: 已實現損益 | Q1: 未實現損益 | R1: 除息 | S1: 手續費 | T1: 健保補充保費 | U1: 實質扣抵稅率 | V1: 扣抵稅率 | W1: 所得稅率 | X1: 投資報酬率 | Y1: 今日股價 | Z1: 漲跌 | AB1: 買進理由 | AC1: 賣出理由
A2: 46031 | C2: 919 | D2: =VLOOKUP(C2,台股行情!A:B,2,FALSE) -> 群益台灣精選高息 | E2: 1000 | F2: 22.98 | G2: =E2*F2 -> 22980 | H2: 32 | I2: 46050 | J2: 24.41 | K2: =E2*J2 -> 24410 | L2: 33 | M2: 23 | N2: 0 | O2: =IF(I2="",E2*Y2,0) -> 0 | P2: =IF(I2="",R2-H2,(K2-H2-SUM(L2:N2)+R2-S2-T2)-G2)+(ROUND(R2*V2,0)-ROUND(R2*(1+V2),0)*W2) -> 1342 | Q2: =IF(I2="",(O2-G2-(O2*0.1425%*0.65)-(O2*0.3%)-S2-T2),0) -> 0 | U2: =(V2*50%)/(1+50%*V2) -> 0 | W2: 0.11 | X2: =(P2+Q2)/G2 -> 0.058398607 | Y2: =VLOOKUP(C2,台股行情!A:D,4,FALSE) -> 32.38 | Z2: =VLOOKUP(C2,台股行情!A:E,5,FALSE) -> -0.11 | AA2: =IF(I2="",((TODAY()-A2)*G2)/365.24,((I2-A2)*G2)/365.24) -> 1195.4331 | AB2: 存股
A3: 46031 | C3: 918 | D3: =VLOOKUP(C3,台股行情!A:B,2,FALSE) -> 大華優利高填息30 | E3: 1000 | F3: 22.71 | G3: =E3*F3 -> 22710 | H3: 32 | I3: 46050 | J3: 23.61 | K3: =E3*J3 -> 23610 | L3: 34 | M3: 24 | N3: 0 | O3: =IF(I3="",E3*Y3,0) -> 0 | P3: =IF(I3="",R3-H3,(K3-H3-SUM(L3:N3)+R3-S3-T3)-G3)+(ROUND(R3*V3,0)-ROUND(R3*(1+V3),0)*W3) -> 810 | Q3: =IF(I3="",(O3-G3-(O3*0.1425%*0.65)-(O3*0.3%)-S3-T3),0) -> 0 | U3: =(V3*50%)/(1+50%*V3) -> 0 | W3: 0.11 | X3: =(P3+Q3)/G3 -> 0.035667107 | Y3: =VLOOKUP(C3,台股行情!A:D,4,FALSE) -> 34.15 | Z3: =VLOOKUP(C3,台股行情!A:E,5,FALSE) -> -0.37 | AA3: =IF(I3="",((TODAY()-A3)*G3)/365.24,((I3-A3)*G3)/365.24) -> 1181.3876 | AB3: 存股
A4: 46027 | C4: 770 | D4: =VLOOKUP(C4,台股行情!A:B,2,FALSE) -> 國泰北美科技 | E4: 172 | F4: 57.98 | G4: 9972 | H4: 1 | I4: 46090 | J4: 50.2 | K4: =E4*J4 -> 8634.4 | L4: =ROUND(J4*E4*0.1425%,0) -> 12 | M4: =ROUND(J4*E4*0.3%,0) -> 26 | N4: 0 | O4: =IF(I4="",E4*Y4,0) -> 0 | P4: =IF(I4="",R4-H4,(K4-H4-SUM(L4:N4)+R4-S4-T4)-G4)+(ROUND(R4*V4,0)-ROUND(R4*(1+V4),0)*W4) -> -733.62 | Q4: =IF(I4="",(O4-G4-(O4*0.1425%*0.65)-(O4*0.3%)-S4-T4),0) -> 0 | R4: 722.4 | U4: =(V4*50%)/(1+50%*V4) -> 0 | W4: 0.11 | X4: =(P4+Q4)/G4 -> -0.07356799 | Y4: =VLOOKUP(C4,台股行情!A:D,4,FALSE) -> 64.35 | Z4: =VLOOKUP(C4,台股行情!A:E,5,FALSE) -> -2.2 | AA4: =IF(I4="",((TODAY()-A4)*G4)/365.24,((I4-A4)*G4)/365.24) -> 1720.0635 | AB4: 存股 | AC4: 美伊戰爭，憂心崩跌，認賠出場
A5: 46037 | C5: 770 | D5: =VLOOKUP(C5,台股行情!A:B,2,FALSE) -> 國泰北美科技 | E5: 171 | F5: 58.44 | G5: 9993 | H5: 1 | I5: 46090 | J5: 50.2 | K5: =E5*J5 -> 8584.2 | L5: =ROUND(J5*E5*0.1425%,0) -> 12 | M5: =ROUND(J5*E5*0.3%,0) -> 26 | N5: 0 | O5: =IF(I5="",E5*Y5,0) -> 0 | P5: =IF(I5="",R5-H5,(K5-H5-SUM(L5:N5)+R5-S5-T5)-G5)+(ROUND(R5*V5,0)-ROUND(R5*(1+V5),0)*W5) -> -808.58 | Q5: =IF(I5="",(O5-G5-(O5*0.1425%*0.65)-(O5*0.3%)-S5-T5),0) -> 0 | R5: 718.2 | U5: =(V5*50%)/(1+50%*V5) -> 0 | W5: 0.11 | X5: =(P5+Q5)/G5 -> -0.08091464 | Y5: =VLOOKUP(C5,台股行情!A:D,4,FALSE) -> 64.35 | Z5: =VLOOKUP(C5,台股行情!A:E,5,FALSE) -> -2.2 | AA5: =IF(I5="",((TODAY()-A5)*G5)/365.24,((I5-A5)*G5)/365.24) -> 1450.0849 | AB5: 存股 | AC5: 美伊戰爭，憂心崩跌，認賠出場
A6: 46049 | C6: 770 | D6: =VLOOKUP(C6,台股行情!A:B,2,FALSE) -> 國泰北美科技 | E6: 186 | F6: 53.64 | G6: 9977 | H6: 1 | I6: 46090 | J6: 50.2 | K6: =E6*J6 -> 9337.2 | L6: =ROUND(J6*E6*0.1425%,0) -> 13 | M6: =ROUND(J6*E6*0.3%,0) -> 28 | N6: 0 | O6: =IF(I6="",E6*Y6,0) -> 0 | P6: =IF(I6="",R6-H6,(K6-H6-SUM(L6:N6)+R6-S6-T6)-G6)+(ROUND(R6*V6,0)-ROUND(R6*(1+V6),0)*W6) -> -42.58 | Q6: =IF(I6="",(O6-G6-(O6*0.1425%*0.65)-(O6*0.3%)-S6-T6),0) -> 0 | R6: 718.2 | U6: =(V6*50%)/(1+50%*V6) -> 0 | W6: 0.11 | X6: =(P6+Q6)/G6 -> -0.004267816 | Y6: =VLOOKUP(C6,台股行情!A:D,4,FALSE) -> 64.35 | Z6: =VLOOKUP(C6,台股行情!A:E,5,FALSE) -> -2.2 | AA6: =IF(I6="",((TODAY()-A6)*G6)/365.24,((I6-A6)*G6)/365.24) -> 1119.9677 | AB6: 存股 | AC6: 美伊戰爭，憂心崩跌，認賠出場
A7: 46058 | C7: 770 | D7: =VLOOKUP(C7,台股行情!A:B,2,FALSE) -> 國泰北美科技 | E7: 192 | F7: 52.04 | G7: 9991 | H7: 1 | I7: 46090 | J7: 50.2 | K7: =E7*J7 -> 9638.4 | L7: =ROUND(J7*E7*0.1425%,0) -> 14 | M7: =ROUND(J7*E7*0.3%,0) -> 29 | N7: 0 | O7: =IF(I7="",E7*Y7,0) -> 0 | P7: =IF(I7="",R7-H7,(K7-H7-SUM(L7:N7)+R7-S7-T7)-G7)+(ROUND(R7*V7,0)-ROUND(R7*(1+V7),0)*W7) -> 246.38 | Q7: =IF(I7="",(O7-G7-(O7*0.1425%*0.65)-(O7*0.3%)-S7-T7),0) -> 0 | R7: 722.4 | U7: =(V7*50%)/(1+50%*V7) -> 0 | W7: 0.11 | X7: =(P7+Q7)/G7 -> 0.024660194 | Y7: =VLOOKUP(C7,台股行情!A:D,4,FALSE) -> 64.35 | Z7: =VLOOKUP(C7,台股行情!A:E,5,FALSE) -> -2.2 | AA7: =IF(I7="",((TODAY()-A7)*G7)/365.24,((I7-A7)*G7)/365.24) -> 875.34772 | AB7: 存股 | AC7: 美伊戰爭，憂心崩跌，獲利了結
A8: 46076 | C8: 770 | D8: =VLOOKUP(C8,台股行情!A:B,2,FALSE) -> 國泰北美科技 | E8: 193 | F8: 51.65 | G8: 9968 | H8: 1 | I8: 46090 | J8: 50.2 | K8: =E8*J8 -> 9688.6 | L8: =ROUND(J8*E8*0.1425%,0) -> 14 | M8: =ROUND(J8*E8*0.3%,0) -> 29 | N8: 0 | O8: =IF(I8="",E8*Y8,0) -> 0 | P8: =IF(I8="",R8-H8,(K8-H8-SUM(L8:N8)+R8-S8-T8)-G8)+(ROUND(R8*V8,0)-ROUND(R8*(1+V8),0)*W8) -> 319.58 | Q8: =IF(I8="",(O8-G8-(O8*0.1425%*0.65)-(O8*0.3%)-S8-T8),0) -> 0 | R8: 722.4 | U8: =(V8*50%)/(1+50%*V8) -> 0 | W8: 0.11 | X8: =(P8+Q8)/G8 -> 0.032060594 | Y8: =VLOOKUP(C8,台股行情!A:D,4,FALSE) -> 64.35 | Z8: =VLOOKUP(C8,台股行情!A:E,5,FALSE) -> -2.2 | AA8: =IF(I8="",((TODAY()-A8)*G8)/365.24,((I8-A8)*G8)/365.24) -> 382.08301 | AB8: 存股 | AC8: 美伊戰爭，憂心崩跌，獲利了結
A9: 46078 | C9: 770 | D9: =VLOOKUP(C9,台股行情!A:B,2,FALSE) -> 國泰北美科技 | E9: 193 | F9: 51.65 | G9: 9968 | H9: 1 | I9: 46090 | J9: 50.2 | K9: =E9*J9 -> 9688.6 | L9: =ROUND(J9*E9*0.1425%,0) -> 14 | M9: =ROUND(J9*E9*0.3%,0) -> 29 | N9: 0 | O9: =IF(I9="",E9*Y9,0) -> 0 | P9: =IF(I9="",R9-H9,(K9-H9-SUM(L9:N9)+R9-S9-T9)-G9)+(ROUND(R9*V9,0)-ROUND(R9*(1+V9),0)*W9) -> 319.58 | Q9: =IF(I9="",(O9-G9-(O9*0.1425%*0.65)-(O9*0.3%)-S9-T9),0) -> 0 | R9: 722.4 | U9: =(V9*50%)/(1+50%*V9) -> 0 | W9: 0.11 | X9: =(P9+Q9)/G9 -> 0.032060594 | Y9: =VLOOKUP(C9,台股行情!A:D,4,FALSE) -> 64.35 | Z9: =VLOOKUP(C9,台股行情!A:E,5,FALSE) -> -2.2 | AA9: =IF(I9="",((TODAY()-A9)*G9)/365.24,((I9-A9)*G9)/365.24) -> 327.49973 | AB9: 存股 | AC9: 美伊戰爭，憂心崩跌，獲利了結
A10: 46090 | C10: 919 | D10: =VLOOKUP(C10,台股行情!A:B,2,FALSE) -> 群益台灣精選高息 | E10: 436 | F10: 22.93 | G10: 9990 | H10: 1 | I10: 46129 | J10: 23.4 | K10: =E10*J10 -> 10202.4 | L10: 17 | M10: 12 | N10: 0 | O10: =IF(I10="",E10*Y10,0) -> 0 | P10: =IF(I10="",R10-H10,(K10-H10-SUM(L10:N10)+R10-S10-T10)-G10)+(ROUND(R10*V10,0)-ROUND(R10*(1+V10),0)*W10) -> 485 | Q10: =IF(I10="",(O10-G10-(O10*0.1425%*0.65)-(O10*0.3%)-S10-T10),0) -> 0 | R10: 340 | U10: =(V10*50%)/(1+50%*V10) -> 0 | W10: 0.11 | X10: =(P10+Q10)/G10 -> 0.048548549 | Y10: =VLOOKUP(C10,台股行情!A:D,4,FALSE) -> 32.38 | Z10: =VLOOKUP(C10,台股行情!A:E,5,FALSE) -> -0.11 | AA10: =IF(I10="",((TODAY()-A10)*G10)/365.24,((I10-A10)*G10)/365.24) -> 1066.7233 | AB10: 存股 | AC10: 賣錯
A11: 46089 | C11: 919 | D11: =VLOOKUP(C11,台股行情!A:B,2,FALSE) -> 群益台灣精選高息 | E11: 428 | F11: 23.36 | G11: 9998 | H11: 1 | I11: 46129 | J11: 23.4 | K11: =E11*J11 -> 10015.2 | L11: 16 | M11: 11 | N11: 0 | O11: =IF(I11="",E11*Y11,0) -> 0 | P11: =IF(I11="",R11-H11,(K11-H11-SUM(L11:N11)+R11-S11-T11)-G11)+(ROUND(R11*V11,0)-ROUND(R11*(1+V11),0)*W11) -> -10.8 | Q11: =IF(I11="",(O11-G11-(O11*0.1425%*0.65)-(O11*0.3%)-S11-T11),0) -> 0 | U11: =(V11*50%)/(1+50%*V11) -> 0 | W11: 0.11 | X11: =(P11+Q11)/G11 -> -0.001080216 | Y11: =VLOOKUP(C11,台股行情!A:D,4,FALSE) -> 32.38 | Z11: =VLOOKUP(C11,台股行情!A:E,5,FALSE) -> -0.11 | AA11: =IF(I11="",((TODAY()-A11)*G11)/365.24,((I11-A11)*G11)/365.24) -> 1094.9513 | AB11: 存股 | AC11: 賣錯
A12: 46126 | C12: 900 | D12: =VLOOKUP(C12,台股行情!A:B,2,FALSE) -> 富邦特選高股息30 | E12: 1000 | F12: 14.72 | G12: =E12*F12 -> 14720 | H12: 20 | I12: 46129 | J12: 15.06 | K12: =E12*J12 -> 15060 | L12: =ROUND(J12*E12*0.1425%,0) -> 21 | M12: 15 | N12: 0 | O12: =IF(I12="",E12*Y12,0) -> 0 | P12: =IF(I12="",R12-H12,(K12-H12-SUM(L12:N12)+R12-S12-T12)-G12)+(ROUND(R12*V12,0)-ROUND(R12*(1+V12),0)*W12) -> 284 | Q12: =IF(I12="",(O12-G12-(O12*0.1425%*0.65)-(O12*0.3%)-S12-T12),0) -> 0 | U12: =(V12*50%)/(1+50%*V12) -> 0 | W12: 0.11 | X12: =(P12+Q12)/G12 -> 0.019293478 | Y12: =VLOOKUP(C12,台股行情!A:D,4,FALSE) -> 19.84 | Z12: =VLOOKUP(C12,台股行情!A:E,5,FALSE) -> -0.13 | AA12: =IF(I12="",((TODAY()-A12)*G12)/365.24,((I12-A12)*G12)/365.24) -> 120.9068 | AB12: 除權息 | AC12: 除息前賣出
A13: 46126 | C13: 934 | D13: =VLOOKUP(C13,台股行情!A:B,2,FALSE) -> 中信成長高股息 | E13: 1000 | F13: 22.38 | G13: =E13*F13 -> 22380 | H13: 31 | I13: 46129 | J13: 22.89 | K13: =E13*J13 -> 22890 | L13: 32 | M13: 22 | N13: 0 | O13: =IF(I13="",E13*Y13,0) -> 0 | P13: =IF(I13="",R13-H13,(K13-H13-SUM(L13:N13)+R13-S13-T13)-G13)+(ROUND(R13*V13,0)-ROUND(R13*(1+V13),0)*W13) -> 425 | Q13: =IF(I13="",(O13-G13-(O13*0.1425%*0.65)-(O13*0.3%)-S13-T13),0) -> 0 | U13: =(V13*50%)/(1+50%*V13) -> 0 | W13: 0.11 | X13: =(P13+Q13)/G13 -> 0.01899017 | Y13: =VLOOKUP(C13,台股行情!A:D,4,FALSE) -> 30.01 | Z13: =VLOOKUP(C13,台股行情!A:E,5,FALSE) -> -0.3 | AA13: =IF(I13="",((TODAY()-A13)*G13)/365.24,((I13-A13)*G13)/365.24) -> 183.82433 | AB13: 除權息 | AC13: 除息前賣出
A14: 46126 | C14: 936 | D14: =VLOOKUP(C14,台股行情!A:B,2,FALSE) -> 台新永續高息中小 | E14: 1000 | F14: 18.05 | G14: =E14*F14 -> 18050 | H14: 25 | I14: 46128 | J14: 18.37 | K14: =E14*J14 -> 18370 | L14: =ROUND(J14*E14*0.1425%,0) -> 26 | M14: 18 | N14: 0 | O14: =IF(I14="",E14*Y14,0) -> 0 | P14: =IF(I14="",R14-H14,(K14-H14-SUM(L14:N14)+R14-S14-T14)-G14)+(ROUND(R14*V14,0)-ROUND(R14*(1+V14),0)*W14) -> 251 | Q14: =IF(I14="",(O14-G14-(O14*0.1425%*0.65)-(O14*0.3%)-S14-T14),0) -> 0 | U14: =(V14*50%)/(1+50%*V14) -> 0 | W14: 0.11 | X14: =(P14+Q14)/G14 -> 0.013905817 | Y14: =VLOOKUP(C14,台股行情!A:D,4,FALSE) -> 21.51 | Z14: =VLOOKUP(C14,台股行情!A:E,5,FALSE) -> -0.3 | AA14: =IF(I14="",((TODAY()-A14)*G14)/365.24,((I14-A14)*G14)/365.24) -> 98.839119 | AB14: 除權息 | AC14: 除息前賣出
A15: 46126 | C15: 944 | D15: =VLOOKUP(C15,台股行情!A:B,2,FALSE) -> 野村趨勢動能高息 | E15: 1000 | F15: 16.4 | G15: =E15*F15 -> 16400 | H15: 23 | I15: 46129 | J15: 16.98 | K15: =E15*J15 -> 16980 | L15: =ROUND(J15*E15*0.1425%,0) -> 24 | M15: 16 | N15: 0 | O15: =IF(I15="",E15*Y15,0) -> 0 | P15: =IF(I15="",R15-H15,(K15-H15-SUM(L15:N15)+R15-S15-T15)-G15)+(ROUND(R15*V15,0)-ROUND(R15*(1+V15),0)*W15) -> 517 | Q15: =IF(I15="",(O15-G15-(O15*0.1425%*0.65)-(O15*0.3%)-S15-T15),0) -> 0 | U15: =(V15*50%)/(1+50%*V15) -> 0 | W15: 0.11 | X15: =(P15+Q15)/G15 -> 0.03152439 | Y15: =VLOOKUP(C15,台股行情!A:D,4,FALSE) -> 22.52 | Z15: =VLOOKUP(C15,台股行情!A:E,5,FALSE) -> -0.24 | AA15: =IF(I15="",((TODAY()-A15)*G15)/365.24,((I15-A15)*G15)/365.24) -> 134.70595 | AB15: 除權息 | AC15: 除息前賣出
A16: 46126 | C16: 56 | D16: =VLOOKUP(C16,台股行情!A:B,2,FALSE) -> 元大高股息 | E16: 1000 | F16: 39.96 | G16: =E16*F16 -> 39960 | H16: 56 | I16: 46134 | J16: 42.3 | K16: =E16*J16 -> 42300 | L16: =ROUND(J16*E16*0.1425%,0) -> 60 | M16: 42 | N16: 0 | O16: =IF(I16="",E16*Y16,0) -> 0 | P16: =IF(I16="",R16-H16,(K16-H16-SUM(L16:N16)+R16-S16-T16)-G16)+(ROUND(R16*V16,0)-ROUND(R16*(1+V16),0)*W16) -> 2182 | Q16: =IF(I16="",(O16-G16-(O16*0.1425%*0.65)-(O16*0.3%)-S16-T16),0) -> 0 | T16: =IF(ROUND(R16*(1+V16),0)>20000,ROUND(ROUND(R16*(1+V16),0)*2%,0),0) -> 0 | U16: =(V16*50%)/(1+50%*V16) -> 0 | W16: 0.11 | X16: =(P16+Q16)/G16 -> 0.054604605 | Y16: =VLOOKUP(C16,台股行情!A:D,4,FALSE) -> 58.25 | Z16: =VLOOKUP(C16,台股行情!A:E,5,FALSE) -> -1.35 | AA16: =IF(I16="",((TODAY()-A16)*G16)/365.24,((I16-A16)*G16)/365.24) -> 875.2601 | AB16: 除權息
A17: 46090 | C17: 2603 | D17: =VLOOKUP(C17,台股行情!A:B,2,FALSE) -> 長榮 | E17: 1000 | F17: 212 | G17: =E17*F17 -> 212000 | H17: 302 | I17: 46136 | J17: 200.5 | K17: =E17*J17 -> 200500 | L17: 285 | M17: 601 | N17: 0 | O17: =IF(I17="",E17*Y17,0) -> 0 | P17: =IF(I17="",R17-H17,(K17-H17-SUM(L17:N17)+R17-S17-T17)-G17)+(ROUND(R17*V17,0)-ROUND(R17*(1+V17),0)*W17) -> -12688 | Q17: =IF(I17="",(O17-G17-(O17*0.1425%*0.65)-(O17*0.3%)-S17-T17),0) -> 0 | T17: =IF(ROUND(R17*(1+V17),0)>20000,ROUND(ROUND(R17*(1+V17),0)*2%,0),0) -> 0 | U17: =(V17*50%)/(1+50%*V17) -> 0 | W17: 0.11 | X17: =(P17+Q17)/G17 -> -0.059849057 | Y17: =VLOOKUP(C17,台股行情!A:D,4,FALSE) -> 257 | Z17: =VLOOKUP(C17,台股行情!A:E,5,FALSE) -> -6 | AA17: =IF(I17="",((TODAY()-A17)*G17)/365.24,((I17-A17)*G17)/365.24) -> 26700.252 | AB17: 美伊戰爭 | AC17: 不如預期，換股操作
A18: 46104 | C18: 3289 | D18: =VLOOKUP(C18,台股行情!A:B,2,FALSE) -> 宜特 | E18: 1000 | F18: 141.5 | G18: =E18*F18 -> 141500 | H18: 201 | I18: 46139 | J18: 172.5 | K18: =E18*J18 -> 172500 | L18: 245 | M18: 517 | N18: 0 | O18: =IF(I18="",E18*Y18,0) -> 0 | P18: =IF(I18="",R18-H18,(K18-H18-SUM(L18:N18)+R18-S18-T18)-G18)+(ROUND(R18*V18,0)-ROUND(R18*(1+V18),0)*W18) -> 31090.55 | Q18: =IF(I18="",(O18-G18-(O18*0.1425%*0.65)-(O18*0.3%)-S18-T18),0) -> 0 | R18: 1195 | S18: 10 | T18: =IF(ROUND(R18*(1+V18),0)>20000,ROUND(ROUND(R18*(1+V18),0)*2%,0),0) -> 0 | U18: =(V18*50%)/(1+50%*V18) -> 0 | W18: 0.11 | X18: =(P18+Q18)/G18 -> 0.2197212 | Y18: =VLOOKUP(C18,台股行情!A:D,4,FALSE) -> 134.5 | Z18: =VLOOKUP(C18,台股行情!A:E,5,FALSE) -> -4.5 | AA18: =IF(I18="",((TODAY()-A18)*G18)/365.24,((I18-A18)*G18)/365.24) -> 13559.577 | AB18: 美伊戰爭，卡達LNG設施遭重創
A19: 46149 | C19: 4938 | D19: =VLOOKUP(C19,台股行情!A:B,2,FALSE) -> 和碩 | E19: 1000 | F19: 84.3 | G19: =E19*F19 -> 84300 | H19: 120 | I19: 46156 | J19: 76.8 | K19: =E19*J19 -> 76800 | L19: =ROUND(J19*E19*0.1425%,0) -> 109 | M19: =ROUND(J19*E19*0.3%,0) -> 230 | N19: 0 | O19: =IF(I19="",E19*Y19,0) -> 0 | P19: =IF(I19="",R19-H19,(K19-H19-SUM(L19:N19)+R19-S19-T19)-G19)+(ROUND(R19*V19,0)-ROUND(R19*(1+V19),0)*W19) -> -7959 | Q19: =IF(I19="",(O19-G19-(O19*0.1425%*0.65)-(O19*0.3%)-S19-T19),0) -> 0 | T19: =IF(ROUND(R19*(1+V19),0)>20000,ROUND(ROUND(R19*(1+V19),0)*2%,0),0) -> 0 | U19: =(V19*50%)/(1+50%*V19) -> 0 | W19: 0.11 | X19: =(P19+Q19)/G19 -> -0.094412811 | Y19: =VLOOKUP(C19,台股行情!A:D,4,FALSE) -> 98.1 | Z19: =VLOOKUP(C19,台股行情!A:E,5,FALSE) -> -1.9 | AA19: =IF(I19="",((TODAY()-A19)*G19)/365.24,((I19-A19)*G19)/365.24) -> 1615.65 | AB19: 賭新聞
A20: 46133 | C20: 5347 | D20: =VLOOKUP(C20,台股行情!A:B,2,FALSE) -> 世界 | E20: 1000 | F20: 141 | G20: =E20*F20 -> 141000 | H20: 200 | I20: 46164 | J20: 161 | K20: =E20*J20 -> 161000 | L20: =ROUND(J20*E20*0.1425%,0) -> 229 | M20: =ROUND(J20*E20*0.3%,0) -> 483 | N20: 0 | O20: =IF(I20="",E20*Y20,0) -> 0 | P20: =IF(I20="",R20-H20,(K20-H20-SUM(L20:N20)+R20-S20-T20)-G20)+(ROUND(R20*V20,0)-ROUND(R20*(1+V20),0)*W20) -> 19088 | Q20: =IF(I20="",(O20-G20-(O20*0.1425%*0.65)-(O20*0.3%)-S20-T20),0) -> 0 | T20: =IF(ROUND(R20*(1+V20),0)>20000,ROUND(ROUND(R20*(1+V20),0)*2%,0),0) -> 0 | U20: =(V20*50%)/(1+50%*V20) -> 0 | W20: 0.11 | X20: =(P20+Q20)/G20 -> 0.13537589 | Y20: =VLOOKUP(C20,台股行情!A:D,4,FALSE) -> 161.5 | Z20: =VLOOKUP(C20,台股行情!A:E,5,FALSE) -> -14.5 | AA20: =IF(I20="",((TODAY()-A20)*G20)/365.24,((I20-A20)*G20)/365.24) -> 11967.473 | AB20: 水某精選
A21: 46120 | C21: 919 | D21: =VLOOKUP(C21,台股行情!A:B,2,FALSE) -> 群益台灣精選高息 | E21: 435 | F21: 22.97 | G21: 9991 | H21: 1 | I21: 46195 | J21: 30.92 | K21: =E21*J21 -> 13450.2 | L21: 15 | M21: 11 | N21: 0 | O21: =IF(I21="",E21*Y21,0) -> 0 | P21: =IF(I21="",R21-H21,(K21-H21-SUM(L21:N21)+R21-S21-T21)-G21)+(ROUND(R21*V21,0)-ROUND(R21*(1+V21),0)*W21) -> 3432.2 | Q21: =IF(I21="",(O21-G21-(O21*0.1425%*0.65)-(O21*0.3%)-S21-T21),0) -> 0 | T21: =IF(ROUND(R21*(1+V21),0)>20000,ROUND(ROUND(R21*(1+V21),0)*2%,0),0) -> 0 | U21: =(V21*50%)/(1+50%*V21) -> 0 | W21: 0.11 | X21: =(P21+Q21)/G21 -> 0.34352918 | Y21: =VLOOKUP(C21,台股行情!A:D,4,FALSE) -> 32.38 | Z21: =VLOOKUP(C21,台股行情!A:E,5,FALSE) -> -0.11 | AA21: =IF(I21="",((TODAY()-A21)*G21)/365.24,((I21-A21)*G21)/365.24) -> 2051.5962 | AB21: 存股
A22: 46132 | C22: 919 | D22: =VLOOKUP(C22,台股行情!A:B,2,FALSE) -> 群益台灣精選高息 | E22: 421 | F22: 23.71 | G22: 9981 | H22: 1 | I22: 46195 | J22: 30.92 | K22: =E22*J22 -> 13017.32 | L22: 16 | M22: 11 | N22: 0 | O22: =IF(I22="",E22*Y22,0) -> 0 | P22: =IF(I22="",R22-H22,(K22-H22-SUM(L22:N22)+R22-S22-T22)-G22)+(ROUND(R22*V22,0)-ROUND(R22*(1+V22),0)*W22) -> 3639.12 | Q22: =IF(I22="",(O22-G22-(O22*0.1425%*0.65)-(O22*0.3%)-S22-T22),0) -> 0 | R22: 720 | S22: 10 | T22: =IF(ROUND(R22*(1+V22),0)>20000,ROUND(ROUND(R22*(1+V22),0)*2%,0),0) -> 0 | U22: =(V22*50%)/(1+50%*V22) -> 0 | W22: 0.11 | X22: =(P22+Q22)/G22 -> 0.36460475 | Y22: =VLOOKUP(C22,台股行情!A:D,4,FALSE) -> 32.38 | Z22: =VLOOKUP(C22,台股行情!A:E,5,FALSE) -> -0.11 | AA22: =IF(I22="",((TODAY()-A22)*G22)/365.24,((I22-A22)*G22)/365.24) -> 1721.6159 | AB22: 存股
A23: 46188 | C23: 692 | D23: =VLOOKUP(C23,台股行情!A:B,2,FALSE) -> 富邦公司治理 | E23: 109 | F23: 91.14 | G23: 9934 | H23: 1 | I23: 46195 | J23: 95.75 | K23: =E23*J23 -> 10436.75 | L23: 14 | M23: 10 | N23: 0 | O23: =IF(I23="",E23*Y23,0) -> 0 | P23: =IF(I23="",R23-H23,(K23-H23-SUM(L23:N23)+R23-S23-T23)-G23)+(ROUND(R23*V23,0)-ROUND(R23*(1+V23),0)*W23) -> 477.75 | Q23: =IF(I23="",(O23-G23-(O23*0.1425%*0.65)-(O23*0.3%)-S23-T23),0) -> 0 | T23: =IF(ROUND(R23*(1+V23),0)>20000,ROUND(ROUND(R23*(1+V23),0)*2%,0),0) -> 0 | U23: =(V23*50%)/(1+50%*V23) -> 0 | W23: 0.11 | X23: =(P23+Q23)/G23 -> 0.04809241 | Y23: =VLOOKUP(C23,台股行情!A:D,4,FALSE) -> 94.4 | Z23: =VLOOKUP(C23,台股行情!A:E,5,FALSE) -> -3.05 | AA23: =IF(I23="",((TODAY()-A23)*G23)/365.24,((I23-A23)*G23)/365.24) -> 190.38988 | AB23: 存股
A27: =MIN(A93:A93) -> 0
A28: 44280 | B28: 普通買進 | C28: 6770 | D28: 力積電 | E28: 2000 | F28: 75.1 | G28: 150200 | H28: 128 | K28: =E28*J28 -> 0 | L28: =ROUND(J28*E28*0.1425%,0) -> 0 | M28: =ROUND(J28*E28*0.3%,0) -> 0 | N28: 0 | O28: =IF(I28="",E28*Y28,0) -> 132400 | P28: =IF(I28="",R28-H28,(K28-H28-SUM(L28:N28)+R28-S28-T28)-G28)+(ROUND(R28*V28,0)-ROUND(R28*(1+V28),0)*W28) -> 9695.82 | Q28: =IF(I28="",(O28-G28-(O28*0.1425%*0.65)-(O28*0.3%)-S28-T28),0) -> -18369.836 | R28: =982+1412+2568+1584+651+3841 -> 11038 | S28: 50 | T28: =IF(ROUND(R28*(1+V28),0)>20000,ROUND(ROUND(R28*(1+V28),0)*2%,0),0) -> 0 | U28: =(V28*50%)/(1+50%*V28) -> 0 | W28: 0.11 | X28: =(P28+Q28)/G28 -> -0.05774977 | Y28: =VLOOKUP(C28,台股行情!A:D,4,FALSE) -> 66.2 | Z28: =VLOOKUP(C28,台股行情!A:E,5,FALSE) -> -4.8 | AA28: =IF(I28="",((TODAY()-A28)*G28)/365.24,((I28-A28)*G28)/365.24) -> 834809.99 | AB28: 水某精選 | AD28: B. 中度套牢（-10%~ -30%）
A29: 44294 | B29: 普通買進 | C29: 3034 | D29: =VLOOKUP(C29,台股行情!A:B,2,FALSE) -> 聯詠 | E29: 1000 | F29: 619 | G29: =E29*F29 -> 619000 | H29: 882 | K29: =E29*J29 -> 0 | L29: =ROUND(J29*E29*0.1425%,0) -> 0 | M29: =ROUND(J29*E29*0.3%,0) -> 0 | N29: 0 | O29: =IF(I29="",E29*Y29,0) -> 565000 | P29: =IF(I29="",R29-H29,(K29-H29-SUM(L29:N29)+R29-S29-T29)-G29)+(ROUND(R29*V29,0)-ROUND(R29*(1+V29),0)*W29) -> 145167 | Q29: =IF(I29="",(O29-G29-(O29*0.1425%*0.65)-(O29*0.3%)-S29-T29),0) -> -59550.331 | R29: =15600+51500+37000+32000+28000 -> 164100 | S29: 50 | T29: =IF(ROUND(R29*(1+V29),0)>20000,ROUND(ROUND(R29*(1+V29),0)*2%,0),0) -> 3282 | U29: =(V29*50%)/(1+50%*V29) -> 0 | W29: 0.11 | X29: =(P29+Q29)/G29 -> 0.13831449 | Y29: =VLOOKUP(C29,台股行情!A:D,4,FALSE) -> 565 | Z29: =VLOOKUP(C29,台股行情!A:E,5,FALSE) -> 5 | AA29: =IF(I29="",((TODAY()-A29)*G29)/365.24,((I29-A29)*G29)/365.24) -> 3416668.5 | AB29: 水某精選
A30: 44300 | B30: 普通買進 | C30: 2458 | D30: =VLOOKUP(C30,台股行情!A:B,2,FALSE) -> 義隆 | E30: 1000 | F30: 204.5 | G30: =E30*F30 -> 204500 | H30: 291 | K30: =E30*J30 -> 0 | L30: =ROUND(J30*E30*0.1425%,0) -> 0 | M30: =ROUND(J30*E30*0.3%,0) -> 0 | N30: 0 | O30: =IF(I30="",E30*Y30,0) -> 135500 | P30: =IF(I30="",R30-H30,(K30-H30-SUM(L30:N30)+R30-S30-T30)-G30)+(ROUND(R30*V30,0)-ROUND(R30*(1+V30),0)*W30) -> 40540.42 | Q30: =IF(I30="",(O30-G30-(O30*0.1425%*0.65)-(O30*0.3%)-S30-T30),0) -> -70510.007 | R30: =9000+13811+3069+2046+3052+4069+3763+2644+4424 -> 45878 | S30: 60 | T30: =IF(ROUND(R30*(1+V30),0)>20000,ROUND(ROUND(R30*(1+V30),0)*2%,0),0) -> 918 | U30: =(V30*50%)/(1+50%*V30) -> 0 | W30: 0.11 | X30: =(P30+Q30)/G30 -> -0.14655055 | Y30: =VLOOKUP(C30,台股行情!A:D,4,FALSE) -> 135.5 | Z30: =VLOOKUP(C30,台股行情!A:E,5,FALSE) -> 2 | AA30: =IF(I30="",((TODAY()-A30)*G30)/365.24,((I30-A30)*G30)/365.24) -> 1125410.7 | AB30: 水某精選 | AD30: B. 中度套牢（-10%~ -30%）
A31: 44308 | B31: 普通買進 | C31: 3481 | D31: =VLOOKUP(C31,台股行情!A:B,2,FALSE) -> 群創 | E31: 1000 | F31: 29.1 | G31: =29100+5965 -> 35065 | H31: =41+8 -> 49 | K31: =E31*J31 -> 0 | L31: =ROUND(J31*E31*0.1425%,0) -> 0 | M31: =ROUND(J31*E31*0.3%,0) -> 0 | N31: 0 | O31: =IF(I31="",E31*Y31,0) -> 48300 | P31: =IF(I31="",R31-H31,(K31-H31-SUM(L31:N31)+R31-S31-T31)-G31)+(ROUND(R31*V31,0)-ROUND(R31*(1+V31),0)*W31) -> 1915.23 | Q31: =IF(I31="",(O31-G31-(O31*0.1425%*0.65)-(O31*0.3%)-S31-T31),0) -> 13025.362 | R31: =398+1054+755 -> 2207 | S31: 20 | T31: =IF(ROUND(R31*(1+V31),0)>20000,ROUND(ROUND(R31*(1+V31),0)*2%,0),0) -> 0 | U31: =(V31*50%)/(1+50%*V31) -> 0 | W31: 0.11 | X31: =(P31+Q31)/G31 -> 0.42608276 | Y31: =VLOOKUP(C31,台股行情!A:D,4,FALSE) -> 48.3 | Z31: =VLOOKUP(C31,台股行情!A:E,5,FALSE) -> -2.6 | AA31: =IF(I31="",((TODAY()-A31)*G31)/365.24,((I31-A31)*G31)/365.24) -> 192202.74 | AB31: 轉型 | AD31: A. 優先汰弱（深套 + 題材弱/循環久）
A32: 45338 | C32: 6196 | D32: =VLOOKUP(C32,台股行情!A:B,2,FALSE) -> 帆宣 | E32: 1000 | F32: 162 | G32: =E32*F32 -> 162000 | H32: 230 | K32: =E32*J32 -> 0 | L32: =ROUND(J32*E32*0.1425%,0) -> 0 | M32: =ROUND(J32*E32*0.3%,0) -> 0 | N32: 0 | O32: =IF(I32="",E32*Y32,0) -> 613000 | P32: =IF(I32="",R32-H32,(K32-H32-SUM(L32:N32)+R32-S32-T32)-G32)+(ROUND(R32*V32,0)-ROUND(R32*(1+V32),0)*W32) -> 16104.17 | Q32: =IF(I32="",(O32-G32-(O32*0.1425%*0.65)-(O32*0.3%)-S32-T32),0) -> 448563.21 | R32: =6000+5905+6448 -> 18353 | S32: 30 | T32: =IF(ROUND(R32*(1+V32),0)>20000,ROUND(ROUND(R32*(1+V32),0)*2%,0),0) -> 0 | U32: =(V32*50%)/(1+50%*V32) -> 0 | W32: 0.11 | X32: =(P32+Q32)/G32 -> 2.8683172 | Y32: =VLOOKUP(C32,台股行情!A:D,4,FALSE) -> 613 | Z32: =VLOOKUP(C32,台股行情!A:E,5,FALSE) -> -43 | AA32: =IF(I32="",((TODAY()-A32)*G32)/365.24,((I32-A32)*G32)/365.24) -> 431124.74 | AB32: 水某精選
A34: 46050 | C34: 00981A | D34: =VLOOKUP(C34,台股行情!A:B,2,FALSE) -> 主動統一台股增長 | E34: 2000 | F34: 18.4 | G34: =E34*F34 -> 36800 | H34: 52 | K34: =E34*J34 -> 0 | L34: =ROUND(J34*E34*0.1425%,0) -> 0 | M34: =ROUND(J34*E34*0.3%,0) -> 0 | N34: 0 | O34: =IF(I34="",E34*Y34,0) -> 58800 | P34: =IF(I34="",R34-H34,(K34-H34-SUM(L34:N34)+R34-S34-T34)-G34)+(ROUND(R34*V34,0)-ROUND(R34*(1+V34),0)*W34) -> 677.8 | Q34: =IF(I34="",(O34-G34-(O34*0.1425%*0.65)-(O34*0.3%)-S34-T34),0) -> 21759.136 | R34: 820 | S34: 10 | T34: =IF(ROUND(R34*(1+V34),0)>20000,ROUND(ROUND(R34*(1+V34),0)*2%,0),0) -> 0 | U34: =(V34*50%)/(1+50%*V34) -> 0 | W34: 0.11 | X34: =(P34+Q34)/G34 -> 0.60969936 | Y34: =VLOOKUP(C34,台股行情!A:D,4,FALSE) -> 29.4 | Z34: =VLOOKUP(C34,台股行情!A:E,5,FALSE) -> -1.79 | AA34: =IF(I34="",((TODAY()-A34)*G34)/365.24,((I34-A34)*G34)/365.24) -> 26196.474 | AB34: 存股
A35: 46051 | C35: 00981A | D35: =VLOOKUP(C35,台股行情!A:B,2,FALSE) -> 主動統一台股增長 | E35: 1000 | F35: 18.21 | G35: =E35*F35 -> 18210 | H35: 25 | K35: =E35*J35 -> 0 | L35: =ROUND(J35*E35*0.1425%,0) -> 0 | M35: =ROUND(J35*E35*0.3%,0) -> 0 | N35: 0 | O35: =IF(I35="",E35*Y35,0) -> 29400 | P35: =IF(I35="",R35-H35,(K35-H35-SUM(L35:N35)+R35-S35-T35)-G35)+(ROUND(R35*V35,0)-ROUND(R35*(1+V35),0)*W35) -> 339.9 | Q35: =IF(I35="",(O35-G35-(O35*0.1425%*0.65)-(O35*0.3%)-S35-T35),0) -> 11064.568 | R35: 410 | S35: 10 | T35: =IF(ROUND(R35*(1+V35),0)>20000,ROUND(ROUND(R35*(1+V35),0)*2%,0),0) -> 0 | U35: =(V35*50%)/(1+50%*V35) -> 0 | W35: 0.11 | X35: =(P35+Q35)/G35 -> 0.62627503 | Y35: =VLOOKUP(C35,台股行情!A:D,4,FALSE) -> 29.4 | Z35: =VLOOKUP(C35,台股行情!A:E,5,FALSE) -> -1.79 | AA35: =IF(I35="",((TODAY()-A35)*G35)/365.24,((I35-A35)*G35)/365.24) -> 12913.126 | AB35: 存股
A36: 46076 | C36: 00981A | D36: =VLOOKUP(C36,台股行情!A:B,2,FALSE) -> 主動統一台股增長 | E36: 523 | F36: 19.11 | G36: 9994 | H36: 1 | K36: =E36*J36 -> 0 | L36: =ROUND(J36*E36*0.1425%,0) -> 0 | M36: =ROUND(J36*E36*0.3%,0) -> 0 | N36: 0 | O36: =IF(I36="",E36*Y36,0) -> 15376.2 | P36: =IF(I36="",R36-H36,(K36-H36-SUM(L36:N36)+R36-S36-T36)-G36)+(ROUND(R36*V36,0)-ROUND(R36*(1+V36),0)*W36) -> 189.46 | Q36: =IF(I36="",(O36-G36-(O36*0.1425%*0.65)-(O36*0.3%)-S36-T36),0) -> 5311.8292 | R36: 214 | S36: 10 | T36: =IF(ROUND(R36*(1+V36),0)>20000,ROUND(ROUND(R36*(1+V36),0)*2%,0),0) -> 0 | U36: =(V36*50%)/(1+50%*V36) -> 0 | W36: 0.11 | X36: =(P36+Q36)/G36 -> 0.55045919 | Y36: =VLOOKUP(C36,台股行情!A:D,4,FALSE) -> 29.4 | Z36: =VLOOKUP(C36,台股行情!A:E,5,FALSE) -> -1.79 | AA36: =IF(I36="",((TODAY()-A36)*G36)/365.24,((I36-A36)*G36)/365.24) -> 6402.9022 | AB36: 存股
A37: 46079 | C37: 00981A | D37: =VLOOKUP(C37,台股行情!A:B,2,FALSE) -> 主動統一台股增長 | E37: 495 | F37: 20.19 | G37: 9994 | H37: 1 | K37: =E37*J37 -> 0 | L37: =ROUND(J37*E37*0.1425%,0) -> 0 | M37: =ROUND(J37*E37*0.3%,0) -> 0 | N37: 0 | O37: =IF(I37="",E37*Y37,0) -> 14553 | P37: =IF(I37="",R37-H37,(K37-H37-SUM(L37:N37)+R37-S37-T37)-G37)+(ROUND(R37*V37,0)-ROUND(R37*(1+V37),0)*W37) -> 179.67 | Q37: =IF(I37="",(O37-G37-(O37*0.1425%*0.65)-(O37*0.3%)-S37-T37),0) -> 4491.8613 | R37: 203 | S37: 10 | T37: =IF(ROUND(R37*(1+V37),0)>20000,ROUND(ROUND(R37*(1+V37),0)*2%,0),0) -> 0 | U37: =(V37*50%)/(1+50%*V37) -> 0 | W37: 0.11 | X37: =(P37+Q37)/G37 -> 0.46743359 | Y37: =VLOOKUP(C37,台股行情!A:D,4,FALSE) -> 29.4 | Z37: =VLOOKUP(C37,台股行情!A:E,5,FALSE) -> -1.79 | AA37: =IF(I37="",((TODAY()-A37)*G37)/365.24,((I37-A37)*G37)/365.24) -> 6320.8137 | AB37: 存股
A38: 46133 | C38: 00981A | D38: =VLOOKUP(C38,台股行情!A:B,2,FALSE) -> 主動統一台股增長 | E38: 982 | F38: 26.34 | G38: =E38*F38 -> 25865.88 | H38: 36 | K38: =E38*J38 -> 0 | L38: =ROUND(J38*E38*0.1425%,0) -> 0 | M38: =ROUND(J38*E38*0.3%,0) -> 0 | N38: 0 | O38: =IF(I38="",E38*Y38,0) -> 28870.8 | P38: =IF(I38="",R38-H38,(K38-H38-SUM(L38:N38)+R38-S38-T38)-G38)+(ROUND(R38*V38,0)-ROUND(R38*(1+V38),0)*W38) -> 3328.2 | Q38: =IF(I38="",(O38-G38-(O38*0.1425%*0.65)-(O38*0.3%)-S38-T38),0) -> 2881.566 | R38: 3780 | S38: 10 | T38: =IF(ROUND(R38*(1+V38),0)>20000,ROUND(ROUND(R38*(1+V38),0)*2%,0),0) -> 0 | U38: =(V38*50%)/(1+50%*V38) -> 0 | W38: 0.11 | X38: =(P38+Q38)/G38 -> 0.24007558 | Y38: =VLOOKUP(C38,台股行情!A:D,4,FALSE) -> 29.4 | Z38: =VLOOKUP(C38,台股行情!A:E,5,FALSE) -> -1.79 | AA38: =IF(I38="",((TODAY()-A38)*G38)/365.24,((I38-A38)*G38)/365.24) -> 12534.938 | AB38: 存股
A39: 46148 | C39: 00981A | D39: =VLOOKUP(C39,台股行情!A:B,2,FALSE) -> 主動統一台股增長 | E39: 1000 | F39: 29.28 | G39: =E39*F39 -> 29280 | H39: 41 | K39: =E39*J39 -> 0 | L39: =ROUND(J39*E39*0.1425%,0) -> 0 | M39: =ROUND(J39*E39*0.3%,0) -> 0 | N39: 0 | O39: =IF(I39="",E39*Y39,0) -> 29400 | P39: =IF(I39="",R39-H39,(K39-H39-SUM(L39:N39)+R39-S39-T39)-G39)+(ROUND(R39*V39,0)-ROUND(R39*(1+V39),0)*W39) -> -41 | Q39: =IF(I39="",(O39-G39-(O39*0.1425%*0.65)-(O39*0.3%)-S39-T39),0) -> 4.56825 | T39: =IF(ROUND(R39*(1+V39),0)>20000,ROUND(ROUND(R39*(1+V39),0)*2%,0),0) -> 0 | U39: =(V39*50%)/(1+50%*V39) -> 0 | W39: 0.11 | X39: =(P39+Q39)/G39 -> -0.0012442538 | Y39: =VLOOKUP(C39,台股行情!A:D,4,FALSE) -> 29.4 | Z39: =VLOOKUP(C39,台股行情!A:E,5,FALSE) -> -1.79 | AA39: =IF(I39="",((TODAY()-A39)*G39)/365.24,((I39-A39)*G39)/365.24) -> 12986.967 | AB39: 存股
A40: 46209 | C40: 00981A | D40: =VLOOKUP(C40,台股行情!A:B,2,FALSE) -> 主動統一台股增長 | E40: 316 | F40: 31.55 | G40: 9969 | H40: 1 | K40: =E40*J40 -> 0 | L40: =ROUND(J40*E40*0.1425%,0) -> 0 | M40: =ROUND(J40*E40*0.3%,0) -> 0 | N40: 0 | O40: =IF(I40="",E40*Y40,0) -> 9290.4 | P40: =IF(I40="",R40-H40,(K40-H40-SUM(L40:N40)+R40-S40-T40)-G40)+(ROUND(R40*V40,0)-ROUND(R40*(1+V40),0)*W40) -> -1 | Q40: =IF(I40="",(O40-G40-(O40*0.1425%*0.65)-(O40*0.3%)-S40-T40),0) -> -715.07643 | T40: =IF(ROUND(R40*(1+V40),0)>20000,ROUND(ROUND(R40*(1+V40),0)*2%,0),0) -> 0 | U40: =(V40*50%)/(1+50%*V40) -> 0 | W40: 0.11 | X40: =(P40+Q40)/G40 -> -0.071830317 | Y40: =VLOOKUP(C40,台股行情!A:D,4,FALSE) -> 29.4 | Z40: =VLOOKUP(C40,台股行情!A:E,5,FALSE) -> -1.79 | AA40: =IF(I40="",((TODAY()-A40)*G40)/365.24,((I40-A40)*G40)/365.24) -> 2756.7326 | AB40: 存股
A41: 46240 | C41: 00981A | D41: =VLOOKUP(C41,台股行情!A:B,2,FALSE) -> 主動統一台股增長 | E41: 348 | F41: 28.66 | G41: 9973 | H41: 1 | K41: =E41*J41 -> 0 | L41: =ROUND(J41*E41*0.1425%,0) -> 0 | M41: =ROUND(J41*E41*0.3%,0) -> 0 | N41: 0 | O41: =IF(I41="",E41*Y41,0) -> 10231.2 | P41: =IF(I41="",R41-H41,(K41-H41-SUM(L41:N41)+R41-S41-T41)-G41)+(ROUND(R41*V41,0)-ROUND(R41*(1+V41),0)*W41) -> -1 | Q41: =IF(I41="",(O41-G41-(O41*0.1425%*0.65)-(O41*0.3%)-S41-T41),0) -> 218.02975 | T41: =IF(ROUND(R41*(1+V41),0)>20000,ROUND(ROUND(R41*(1+V41),0)*2%,0),0) -> 0 | U41: =(V41*50%)/(1+50%*V41) -> 0 | W41: 0.11 | X41: =(P41+Q41)/G41 -> 0.021761732 | Y41: =VLOOKUP(C41,台股行情!A:D,4,FALSE) -> 29.4 | Z41: =VLOOKUP(C41,台股行情!A:E,5,FALSE) -> -1.79 | AA41: =IF(I41="",((TODAY()-A41)*G41)/365.24,((I41-A41)*G41)/365.24) -> 1911.3733 | AB41: 台股 ETF
A42: 46087 | C42: 00991A | D42: =VLOOKUP(C42,台股行情!A:B,2,FALSE) -> 主動復華未來50 | E42: 825 | F42: 12.11 | G42: 9990 | H42: 1 | K42: =E42*J42 -> 0 | L42: =ROUND(J42*E42*0.1425%,0) -> 0 | M42: =ROUND(J42*E42*0.3%,0) -> 0 | N42: 0 | O42: =IF(I42="",E42*Y42,0) -> 14165.25 | P42: =IF(I42="",R42-H42,(K42-H42-SUM(L42:N42)+R42-S42-T42)-G42)+(ROUND(R42*V42,0)-ROUND(R42*(1+V42),0)*W42) -> -1 | Q42: =IF(I42="",(O42-G42-(O42*0.1425%*0.65)-(O42*0.3%)-S42-T42),0) -> 4119.6337 | T42: =IF(ROUND(R42*(1+V42),0)>20000,ROUND(ROUND(R42*(1+V42),0)*2%,0),0) -> 0 | U42: =(V42*50%)/(1+50%*V42) -> 0 | W42: 0.11 | X42: =(P42+Q42)/G42 -> 0.41227564 | Y42: =VLOOKUP(C42,台股行情!A:D,4,FALSE) -> 17.17 | Z42: =VLOOKUP(C42,台股行情!A:E,5,FALSE) -> -1.13 | AA42: =IF(I42="",((TODAY()-A42)*G42)/365.24,((I42-A42)*G42)/365.24) -> 6099.4688 | AB42: 存股
A43: 46097 | C43: 00991A | D43: =VLOOKUP(C43,台股行情!A:B,2,FALSE) -> 主動復華未來50 | E43: 798 | F43: 12.53 | G43: 9998 | H43: 1 | K43: =E43*J43 -> 0 | L43: =ROUND(J43*E43*0.1425%,0) -> 0 | M43: =ROUND(J43*E43*0.3%,0) -> 0 | N43: 0 | O43: =IF(I43="",E43*Y43,0) -> 13701.66 | P43: =IF(I43="",R43-H43,(K43-H43-SUM(L43:N43)+R43-S43-T43)-G43)+(ROUND(R43*V43,0)-ROUND(R43*(1+V43),0)*W43) -> -1 | Q43: =IF(I43="",(O43-G43-(O43*0.1425%*0.65)-(O43*0.3%)-S43-T43),0) -> 3649.8639 | T43: =IF(ROUND(R43*(1+V43),0)>20000,ROUND(ROUND(R43*(1+V43),0)*2%,0),0) -> 0 | U43: =(V43*50%)/(1+50%*V43) -> 0 | W43: 0.11 | X43: =(P43+Q43)/G43 -> 0.36495938 | Y43: =VLOOKUP(C43,台股行情!A:D,4,FALSE) -> 17.17 | Z43: =VLOOKUP(C43,台股行情!A:E,5,FALSE) -> -1.13 | AA43: =IF(I43="",((TODAY()-A43)*G43)/365.24,((I43-A43)*G43)/365.24) -> 5830.6155 | AB43: 存股
A44: 46119 | C44: 00991A | D44: =VLOOKUP(C44,台股行情!A:B,2,FALSE) -> 主動復華未來50 | E44: 790 | F44: 12.65 | G44: 9993 | H44: 1 | K44: =E44*J44 -> 0 | L44: =ROUND(J44*E44*0.1425%,0) -> 0 | M44: =ROUND(J44*E44*0.3%,0) -> 0 | N44: 0 | O44: =IF(I44="",E44*Y44,0) -> 13564.3 | P44: =IF(I44="",R44-H44,(K44-H44-SUM(L44:N44)+R44-S44-T44)-G44)+(ROUND(R44*V44,0)-ROUND(R44*(1+V44),0)*W44) -> -1 | Q44: =IF(I44="",(O44-G44-(O44*0.1425%*0.65)-(O44*0.3%)-S44-T44),0) -> 3518.0432 | T44: =IF(ROUND(R44*(1+V44),0)>20000,ROUND(ROUND(R44*(1+V44),0)*2%,0),0) -> 0 | U44: =(V44*50%)/(1+50%*V44) -> 0 | W44: 0.11 | X44: =(P44+Q44)/G44 -> 0.35195068 | Y44: =VLOOKUP(C44,台股行情!A:D,4,FALSE) -> 17.17 | Z44: =VLOOKUP(C44,台股行情!A:E,5,FALSE) -> -1.13 | AA44: =IF(I44="",((TODAY()-A44)*G44)/365.24,((I44-A44)*G44)/365.24) -> 5225.7776 | AB44: 存股
...

Sheet 25
A1: 買進日期 | B1: 種類 | C1: 股票代號 | D1: 股票名稱 | E1: 股數 | F1: 買進價 | G1: 成交金額 | H1: 手續費 | I1: 賣出日期 | J1: 賣出價 | K1: 成交金額 | L1: 手續費 | M1: 交易稅 | N1: 證所稅 | O1: 參考現值 | P1: 已實現損益 | Q1: 未實現損益 | R1: 除息 | S1: 手續費 | T1: 健保補充保費 | U1: 實質扣抵稅率 | V1: 扣抵稅率 | W1: 所得稅率 | X1: 投資報酬率 | Y1: 今日股價 | Z1: 漲跌 | AB1: 買進理由 | AC1: 賣出理由
A2: 45695 | C2: 6438 | D2: 迅得 | E2: 1000 | F2: 248.5 | G2: 248500 | H2: 354 | I2: 45702 | J2: 216.5 | K2: 216500 | L2: 308 | M2: 649 | N2: 0 | O2: 0 | P2: -33311 | Q2: 0 | U2: 0 | W2: 0.11 | X2: -0.13404829 | Y2: =VLOOKUP(C2,台股行情!A:D,4,FALSE) -> 180 | Z2: =VLOOKUP(C2,台股行情!A:E,5,FALSE) -> -2 | AA2: =IF(I2="",((TODAY()-A2)*G2)/365.24,((I2-A2)*G2)/365.24) -> 4762.6218 | AB2: 動能股 | AC2: 破 10MA，認賠出場
A3: 45696 | C3: 6245 | D3: 立端 | E3: 1000 | F3: 114 | G3: 114000 | H3: 162 | I3: 45705 | J3: 108.5 | K3: 108500 | L3: 154 | M3: 325 | N3: 0 | O3: 0 | P3: -6141 | Q3: 0 | U3: 0 | W3: 0.11 | X3: -0.053868421 | Y3: =VLOOKUP(C3,台股行情!A:D,4,FALSE) -> 87.7 | Z3: =VLOOKUP(C3,台股行情!A:E,5,FALSE) -> -2 | AA3: =IF(I3="",((TODAY()-A3)*G3)/365.24,((I3-A3)*G3)/365.24) -> 2809.1118 | AB3: 動能股 | AC3: 破 10MA，認賠出場
A4: 45707 | C4: 2377 | D4: 微星 | E4: 1000 | F4: 202.5 | G4: 202500 | H4: 288 | I4: 45713 | J4: 195 | K4: 195000 | L4: 277 | M4: 585 | N4: 0 | O4: 0 | P4: -8650 | Q4: 0 | U4: 0 | W4: 0.11 | X4: -0.042716049 | Y4: =VLOOKUP(C4,台股行情!A:D,4,FALSE) -> 158 | Z4: =VLOOKUP(C4,台股行情!A:E,5,FALSE) -> -1 | AA4: =IF(I4="",((TODAY()-A4)*G4)/365.24,((I4-A4)*G4)/365.24) -> 3326.5798 | AB4: 動能股 | AC4: 破 10MA，認賠出場
A5: 45702 | C5: 2301 | D5: 光寶科 | E5: 1000 | F5: 110 | G5: 110000 | H5: 156 | I5: 45715 | J5: 110 | K5: 110000 | L5: 156 | M5: 330 | N5: 0 | O5: 0 | P5: -642 | Q5: 0 | U5: 0 | W5: 0.11 | X5: -0.0058363636 | Y5: =VLOOKUP(C5,台股行情!A:D,4,FALSE) -> 268 | Z5: =VLOOKUP(C5,台股行情!A:E,5,FALSE) -> -15 | AA5: =IF(I5="",((TODAY()-A5)*G5)/365.24,((I5-A5)*G5)/365.24) -> 3915.2338 | AB5: 動能股 | AC5: 破 10MA，認賠出場
A6: 45696 | C6: 6206 | D6: 元大上證50 | E6: 1000 | F6: 117 | G6: 117000 | H6: 166 | I6: 45715 | J6: 162.5 | K6: 162500 | L6: 231 | M6: 487 | N6: 0 | O6: 0 | P6: 44616 | Q6: 0 | U6: 0 | W6: 0.11 | X6: 0.38133333 | Y6: =VLOOKUP(C6,台股行情!A:D,4,FALSE) -> 36.16 | Z6: =VLOOKUP(C6,台股行情!A:E,5,FALSE) -> -0.59 | AA6: =IF(I6="",((TODAY()-A6)*G6)/365.24,((I6-A6)*G6)/365.24) -> 6086.4089 | AB6: 動能股 | AC6: 破 10MA，獲利了結
A7: 45702 | C7: 1605 | D7: 華新 | E7: 1000 | F7: 26.85 | G7: 26850 | H7: 38 | I7: 45720 | J7: 27.6 | K7: 27600 | L7: 39 | M7: 83 | N7: 0 | O7: 0 | P7: 590 | Q7: 0 | U7: 0 | W7: 0.11 | X7: 0.021973929 | Y7: =VLOOKUP(C7,台股行情!A:D,4,FALSE) -> 37.7 | Z7: =VLOOKUP(C7,台股行情!A:E,5,FALSE) -> -3 | AA7: =IF(I7="",((TODAY()-A7)*G7)/365.24,((I7-A7)*G7)/365.24) -> 1323.2395 | AB7: 動能股 | AC7: 破 10MA，獲利了結
A8: 45702 | C8: 1605 | D8: 華新 | E8: 1000 | F8: 26.75 | G8: 26750 | H8: 38 | I8: 45720 | J8: 27.6 | K8: 27600 | L8: 39 | M8: 82 | N8: 0 | O8: 0 | P8: 691 | Q8: 0 | U8: 0 | W8: 0.11 | X8: 0.025831776 | Y8: =VLOOKUP(C8,台股行情!A:D,4,FALSE) -> 37.7 | Z8: =VLOOKUP(C8,台股行情!A:E,5,FALSE) -> -3 | AA8: =IF(I8="",((TODAY()-A8)*G8)/365.24,((I8-A8)*G8)/365.24) -> 1318.3112 | AB8: 動能股 | AC8: 破 10MA，獲利了結
A9: 45706 | C9: 1536 | D9: 和大 | E9: 1000 | F9: 81.4 | G9: 81400 | H9: 115 | I9: 45720 | J9: 77.9 | K9: 77900 | L9: 111 | M9: 233 | N9: 0 | O9: 0 | P9: -3959 | Q9: 0 | U9: 0 | W9: 0.11 | X9: -0.048636364 | Y9: =VLOOKUP(C9,台股行情!A:D,4,FALSE) -> 44.3 | Z9: =VLOOKUP(C9,台股行情!A:E,5,FALSE) -> -0.9 | AA9: =IF(I9="",((TODAY()-A9)*G9)/365.24,((I9-A9)*G9)/365.24) -> 3120.1402 | AB9: 動能股 | AC9: 破 10MA，認賠出場
A10: 45702 | C10: 2884 | D10: 玉山金 | E10: 2000 | F10: 29.1 | G10: 58200 | H10: 82 | I10: 45721 | J10: 29.15 | K10: 58300 | L10: 83 | M10: 174 | N10: 0 | O10: 0 | P10: -239 | Q10: 0 | U10: 0 | W10: 0.11 | X10: -0.0041065292 | Y10: =VLOOKUP(C10,台股行情!A:D,4,FALSE) -> 48.8 | Z10: =VLOOKUP(C10,台股行情!A:E,5,FALSE) -> 1.5 | AA10: =IF(I10="",((TODAY()-A10)*G10)/365.24,((I10-A10)*G10)/365.24) -> 3027.5983 | AB10: 動能股 | AC10: 破 10MA，認賠出場
A11: 45722 | C11: 6104 | D11: 創惟 | E11: 1000 | F11: 177.5 | G11: 177500 | H11: 252 | I11: 45726 | J11: 160.5 | K11: 160500 | L11: 228 | M11: 481 | N11: 0 | O11: 0 | P11: -17961 | Q11: 0 | U11: 0 | W11: 0.11 | X11: -0.10118873 | Y11: =VLOOKUP(C11,台股行情!A:D,4,FALSE) -> 85.9 | Z11: =VLOOKUP(C11,台股行情!A:E,5,FALSE) -> -2.1 | AA11: =IF(I11="",((TODAY()-A11)*G11)/365.24,((I11-A11)*G11)/365.24) -> 1943.9273 | AB11: 動能股 | AC11: 破 10MA，認賠出場
A12: 45702 | C12: 2606 | D12: 裕民 | E12: 1000 | F12: 69.5 | G12: 69500 | H12: 99 | I12: 45728 | J12: 71.3 | K12: 71300 | L12: 101 | M12: 213 | N12: 0 | O12: 0 | P12: 1387 | Q12: 0 | U12: 0 | W12: 0.11 | X12: 0.019956835 | Y12: =VLOOKUP(C12,台股行情!A:D,4,FALSE) -> 76 | Z12: =VLOOKUP(C12,台股行情!A:E,5,FALSE) -> -2.2 | AA12: =IF(I12="",((TODAY()-A12)*G12)/365.24,((I12-A12)*G12)/365.24) -> 4947.4318 | AB12: 動能股 | AC12: 破 10MA，獲利了結
A13: 45713 | C13: 2637 | D13: 慧洋-KY | E13: 1000 | F13: 84.4 | G13: 84400 | H13: 120 | I13: 45728 | J13: 82.8 | K13: 82800 | L13: 117 | M13: 248 | N13: 0 | O13: 0 | P13: -2085 | Q13: 0 | U13: 0 | W13: 0.11 | X13: -0.024703791 | Y13: =VLOOKUP(C13,台股行情!A:D,4,FALSE) -> 101 | Z13: =VLOOKUP(C13,台股行情!A:E,5,FALSE) -> -2.5 | AA13: =IF(I13="",((TODAY()-A13)*G13)/365.24,((I13-A13)*G13)/365.24) -> 3466.214 | AB13: 動能股 | AC13: 破 10MA，認賠出場
... A15: 45713 | C15: 9958 | D15: 世紀鋼 | E15: 1000 | F15: 187 | G15: 187000 | H15: 266 | I15: 45742 | J15: 184.5 | K15: 184500 | L15: 262 | M15: 553 | N15: 0 | O15: 0 | P15: -3581 | Q15: 0 | U15: 0 | W15: 0.11 | X15: -0.019149733 | Y15: =VLOOKUP(C15,台股行情!A:D,4,FALSE) -> 88.5 | Z15: =VLOOKUP(C15,台股行情!A:E,5,FALSE) -> -2 | AA15: =IF(I15="",((TODAY()-A15)*G15)/365.24,((I15-A15)*G15)/365.24) -> 14847.771 | AB15: 動能股 | AC15: 破 10MA，認賠出場
A16: 45835 | C16: 3265 | D16: 台星科 | E16: 1000 | F16: 100.5 | G16: 100500 | H16: 143 | I16: 45855 | J16: 102.5 | K16: 102500 | L16: 146 | M16: 307 | N16: 0 | O16: 0 | P16: 5488 | Q16: 0 | R16: 4600 | S16: 10 | U16: 0 | W16: 0.11 | X16: 0.054606965 | Y16: =VLOOKUP(C16,台股行情!A:D,4,FALSE) -> 278 | Z16: =VLOOKUP(C16,台股行情!A:E,5,FALSE) -> -14.5 | AA16: =IF(I16="",((TODAY()-A16)*G16)/365.24,((I16-A16)*G16)/365.24) -> 5503.2308 | AB16: 除權息 | AC16: 已填息
A17: 45835 | C17: 2317 | D17: 鴻海 | E17: 1000 | F17: 164.5 | G17: 164500 | H17: 234 | I17: 228482 | J17: 165.5 | K17: 165500 | L17: 235 | M17: 496 | N17: 0 | O17: 0 | P17: 5187 | Q17: 0 | R17: 5800 | S17: 10 | U17: 0 | W17: 0.11 | X17: 0.031531915 | Y17: =VLOOKUP(C17,台股行情!A:D,4,FALSE) -> 239.5 | Z17: =VLOOKUP(C17,台股行情!A:E,5,FALSE) -> -3.5 | AA17: =IF(I17="",((TODAY()-A17)*G17)/365.24,((I17-A17)*G17)/365.24) -> 82262160 | AB17: 除權息 | AC17: 已填息
A18: 45835 | C18: 9935 | D18: 慶豐富 | E18: 2000 | F18: 23.95 | G18: 47900 | H18: 68 | I18: 45862 | J18: 20.75 | K18: 41500 | L18: 59 | M18: 124 | N18: 0 | O18: 0 | P18: -3457 | Q18: 0 | R18: 3600 | S18: 10 | U18: 0 | W18: 0.11 | X18: -0.07217119 | Y18: =VLOOKUP(C18,台股行情!A:D,4,FALSE) -> 18.65 | Z18: =VLOOKUP(C18,台股行情!A:E,5,FALSE) -> -0.2 | AA18: =IF(I18="",((TODAY()-A18)*G18)/365.24,((I18-A18)*G18)/365.24) -> 3540.9594 | AB18: 除權息 | AC18: 除息後股價不動，成交量低，認賠出場
A19: 45747 | C19: 3661 | D19: 世芯-KY | E19: 10 | F19: 2840 | G19: 28400 | H19: 40 | I19: 45863 | J19: 3945 | K19: 39450 | L19: 56 | M19: 118 | N19: 0 | O19: 0 | P19: 10836 | Q19: 0 | U19: 0 | W19: 0.11 | X19: 0.3815493 | Y19: =VLOOKUP(C19,台股行情!A:D,4,FALSE) -> 3705 | Z19: =VLOOKUP(C19,台股行情!A:E,5,FALSE) -> -235 | AA19: =IF(I19="",((TODAY()-A19)*G19)/365.24,((I19-A19)*G19)/365.24) -> 9019.8226 | AB19: 存股 | AC19: 近上通道。獲利了結
A20: 45849 | C20: 2355 | D20: 敬鵬 | E20: 2000 | F20: 32.35 | G20: 64700 | H20: 92 | I20: 45866 | J20: 32.95 | K20: 65900 | L20: 93 | M20: 197 | N20: 0 | O20: 0 | P20: 4101 | Q20: 0 | R20: 3700 | S20: 10 | U20: 0 | W20: 0.11 | X20: 0.063384853 | Y20: =VLOOKUP(C20,台股行情!A:D,4,FALSE) -> 53.6 | Z20: =VLOOKUP(C20,台股行情!A:E,5,FALSE) -> 1.7 | AA20: =IF(I20="",((TODAY()-A20)*G20)/365.24,((I20-A20)*G20)/365.24) -> 3011.4445 | AB20: 除權息 | AC20: 已填息
A21: 45849 | C21: 2634 | D21: 漢翔 | E21: 2000 | F21: 42.1 | G21: 84200 | H21: 119 | I21: 45866 | J21: 42.35 | K21: 84700 | L21: 120 | M21: 254 | N21: 0 | O21: 0 | P21: 7 | Q21: 0 | U21: 0 | W21: 0.11 | X21: 8.3135392e-05 | Y21: =VLOOKUP(C21,台股行情!A:D,4,FALSE) -> 60.7 | Z21: =VLOOKUP(C21,台股行情!A:E,5,FALSE) -> -1.4 | AA21: =IF(I21="",((TODAY()-A21)*G21)/365.24,((I21-A21)*G21)/365.24) -> 3919.0669 | AB21: 除權息 | AC21: 已填息
A22: 45695 | C22: 3661 | D22: 世芯-KY | E22: 10 | F22: 3455 | G22: 34550 | H22: 49 | I22: 45869 | J22: 3870 | K22: 38700 | L22: 55 | M22: 116 | N22: 0 | O22: 0 | P22: 3930 | Q22: 0 | U22: 0 | W22: 0.11 | X22: 0.11374819 | Y22: =VLOOKUP(C22,台股行情!A:D,4,FALSE) -> 3705 | Z22: =VLOOKUP(C22,台股行情!A:E,5,FALSE) -> -235 | AA22: =IF(I22="",((TODAY()-A22)*G22)/365.24,((I22-A22)*G22)/365.24) -> 16459.588 | AB22: 存股 | AC22: 波段操作，獲利了結
A23: 45868 | C23: 3661 | D23: 世芯-KY | E23: 10 | F23: 3760 | G23: 37600 | H23: 53 | I23: 45869 | J23: 3870 | K23: 38700 | L23: 55 | M23: 116 | N23: 0 | O23: 0 | P23: 876 | Q23: 0 | U23: 0 | W23: 0.11 | X23: 0.023297872 | Y23: =VLOOKUP(C23,台股行情!A:D,4,FALSE) -> 3705 | Z23: =VLOOKUP(C23,台股行情!A:E,5,FALSE) -> -235 | AA23: =IF(I23="",((TODAY()-A23)*G23)/365.24,((I23-A23)*G23)/365.24) -> 102.94601 | AB23: 存股 | AC23: 波段操作，獲利了結
A24: 45695 | C24: 3661 | D24: 世芯-KY | E24: 10 | F24: 3455 | G24: 34550 | H24: 49 | I24: 45881 | J24: 4055 | K24: 40550 | L24: 57 | M24: 121 | N24: 0 | O24: 0 | P24: 5773 | Q24: 0 | U24: 0 | W24: 0.11 | X24: 0.16709117 | Y24: =VLOOKUP(C24,台股行情!A:D,4,FALSE) -> 3705 | Z24: =VLOOKUP(C24,台股行情!A:E,5,FALSE) -> -235 | AA24: =IF(I24="",((TODAY()-A24)*G24)/365.24,((I24-A24)*G24)/365.24) -> 17594.732 | AB24: 存股 | AC24: 波段操作，獲利了結
A25: 45695 | C25: 3661 | D25: 世芯-KY | E25: 20 | F25: 3455 | G25: 69100 | H25: 98 | I25: 45898 | J25: 4120 | K25: 82400 | L25: 117 | M25: 247 | N25: 0 | O25: 0 | P25: 12838 | Q25: 0 | U25: 0 | W25: 0.11 | X25: 0.18578871 | Y25: =VLOOKUP(C25,台股行情!A:D,4,FALSE) -> 3705 | Z25: =VLOOKUP(C25,台股行情!A:E,5,FALSE) -> -235 | AA25: =IF(I25="",((TODAY()-A25)*G25)/365.24,((I25-A25)*G25)/365.24) -> 38405.706 | AB25: 存股 | AC25: 波段操作，獲利了結
A26: 45695 | C26: 3661 | D26: 世芯-KY | E26: 20 | F26: 3455 | G26: 69100 | H26: 98 | I26: 45909 | J26: 3930 | K26: 78600 | L26: 112 | M26: 235 | N26: 0 | O26: 0 | P26: 9055 | Q26: 0 | U26: 0 | W26: 0.11 | X26: 0.13104197 | Y26: =VLOOKUP(C26,台股行情!A:D,4,FALSE) -> 3705 | Z26: =VLOOKUP(C26,台股行情!A:E,5,FALSE) -> -235 | AA26: =IF(I26="",((TODAY()-A26)*G26)/365.24,((I26-A26)*G26)/365.24) -> 40486.803 | AB26: 存股 | AC26: 波段操作，獲利了結
A27: 45695 | C27: 3661 | D27: 世芯-KY | E27: 10 | F27: 3455 | G27: 34550 | H27: 49 | I27: 45909 | J27: 3975 | K27: 39750 | L27: 56 | M27: 119 | N27: 0 | O27: 0 | P27: 4976 | Q27: 0 | U27: 0 | W27: 0.11 | X27: 0.14402315 | Y27: =VLOOKUP(C27,台股行情!A:D,4,FALSE) -> 3705 | Z27: =VLOOKUP(C27,台股行情!A:E,5,FALSE) -> -235 | AA27: =IF(I27="",((TODAY()-A27)*G27)/365.24,((I27-A27)*G27)/365.24) -> 20243.402 | AB27: 存股 | AC27: 波段操作，獲利了結
A28: 45917 | C28: 2542 | D28: 興富發 | E28: 2000 | F28: 46.2 | G28: 92400 | H28: 131 | I28: 45923 | J28: 44.8 | K28: 89600 | L28: 127 | M28: 268 | N28: 0 | O28: 0 | P28: -3326 | Q28: 0 | U28: 0 | W28: 0.11 | X28: -0.035995671 | Y28: =VLOOKUP(C28,台股行情!A:D,4,FALSE) -> 39.35 | Z28: =VLOOKUP(C28,台股行情!A:E,5,FALSE) -> -0.35 | AA28: =IF(I28="",((TODAY()-A28)*G28)/365.24,((I28-A28)*G28)/365.24) -> 1517.906 | AB28: 阿水一式
A29: 45889 | C29: 3661 | D29: 世芯-KY | E29: 10 | F29: 3800 | G29: 38000 | H29: 54 | I29: 45939 | J29: 3485 | K29: 34850 | L29: 49 | M29: 104 | N29: 0 | O29: 0 | P29: -3357 | Q29: 0 | U29: 0 | W29: 0.11 | X29: -0.088342105 | Y29: =VLOOKUP(C29,台股行情!A:D,4,FALSE) -> 3705 | Z29: =VLOOKUP(C29,台股行情!A:E,5,FALSE) -> -235 | AA29: =IF(I29="",((TODAY()-A29)*G29)/365.24,((I29-A29)*G29)/365.24) -> 5202.0589 | AB29: 存股 | AC29: 股價持續下跌，減碼持股
A30: 45924 | C30: 3661 | D30: 世芯-KY | E30: 20 | F30: 3415 | G30: 68300 | H30: 97 | I30: 45968 | J30: 3610 | K30: 72200 | L30: 102 | M30: 216 | N30: 0 | O30: 0 | P30: 3485 | Q30: 0 | U30: 0 | W30: 0.11 | X30: 0.05102489 | Y30: =VLOOKUP(C30,台股行情!A:D,4,FALSE) -> 3705 | Z30: =VLOOKUP(C30,台股行情!A:E,5,FALSE) -> -235 | AA30: =IF(I30="",((TODAY()-A30)*G30)/365.24,((I30-A30)*G30)/365.24) -> 8228.0145 | AB30: 存股 | AC30: 波段操作，獲利了結
A31: 45695 | C31: 3661 | D31: 世芯-KY | E31: 10 | F31: 3455 | G31: 34550 | H31: 49 | I31: 45972 | J31: 3680 | K31: 36800 | L31: 52 | M31: 110 | N31: 0 | O31: 0 | P31: 2039 | Q31: 0 | U31: 0 | W31: 0.11 | X31: 0.059015919 | Y31: =VLOOKUP(C31,台股行情!A:D,4,FALSE) -> 3705 | Z31: =VLOOKUP(C31,台股行情!A:E,5,FALSE) -> -235 | AA31: =IF(I31="",((TODAY()-A31)*G31)/365.24,((I31-A31)*G31)/365.24) -> 26202.908 | AB31: 存股 | AC31: 波段操作，獲利了結
A32: 45944 | C32: 3661 | D32: 世芯-KY | E32: 10 | F32: 3170 | G32: 31700 | H32: 45 | I32: 45978 | J32: 3615 | K32: 36150 | L32: 51 | M32: 108 | N32: 0 | O32: 0 | P32: 4246 | Q32: 0 | U32: 0 | W32: 0.11 | X32: 0.13394322 | Y32: =VLOOKUP(C32,台股行情!A:D,4,FALSE) -> 3705 | Z32: =VLOOKUP(C32,台股行情!A:E,5,FALSE) -> -235 | AA32: =IF(I32="",((TODAY()-A32)*G32)/365.24,((I32-A32)*G32)/365.24) -> 2950.9364 | AB32: 存股 | AC32: 波段操作，獲利了結
A33: 45695 | C33: 3661 | D33: 世芯-KY | E33: 20 | F33: 3455 | G33: 69100 | H33: 100 | I33: 46001 | J33: 3360 | K33: 67200 | L33: 96 | M33: 202 | N33: 0 | O33: 0 | P33: -25.83 | Q33: 0 | R33: 2553 | U33: 0 | W33: 0.11 | X33: -0.00037380608 | Y33: =VLOOKUP(C33,台股行情!A:D,4,FALSE) -> 3705 | Z33: =VLOOKUP(C33,台股行情!A:E,5,FALSE) -> -235 | AA33: =IF(I33="",((TODAY()-A33)*G33)/365.24,((I33-A33)*G33)/365.24) -> 57892.345 | AB33: 存股 | AC33: 股價持續下跌，減碼持股
A34: 45666 | C34: 926 | D34: 凱基全球菁英55 | E34: 4000 | F34: 22.11 | G34: 88440 | H34: 126 | I34: 46003 | J34: 24.66 | K34: 98640 | L34: 140 | M34: 98 | N34: 0 | O34: 0 | P34: 9836 | Q34: 0 | U34: 0 | W34: 0.11 | X34: 0.11121664 | Y34: =VLOOKUP(C34,台股行情!A:D,4,FALSE) -> 27.25 | Z34: =VLOOKUP(C34,台股行情!A:E,5,FALSE) -> -0.22 | AA34: =IF(I34="",((TODAY()-A34)*G34)/365.24,((I34-A34)*G34)/365.24) -> 81601.906 | AB34: 存股
A35: 45915 | C35: 3661 | D35: 世芯-KY | E35: 10 | F35: 3740 | G35: 37400 | H35: 53 | I35: 46024 | J35: 3655 | K35: 36550 | L35: 52 | M35: 109 | N35: 0 | O35: 0 | P35: -1064 | Q35: 0 | U35: 0 | W35: 0.11 | X35: -0.028449198 | Y35: =VLOOKUP(C35,台股行情!A:D,4,FALSE) -> 3705 | Z35: =VLOOKUP(C35,台股行情!A:E,5,FALSE) -> -235 | AA35: =IF(I35="",((TODAY()-A35)*G35)/365.24,((I35-A35)*G35)/365.24) -> 11161.428 | AB35: 存股 | AC35: 出清，換股操作
A36: 45925 | C36: 770 | D36: =VLOOKUP(C36,台股行情!A:B,2,FALSE) -> 國泰北美科技 | E36: 185 | F36: 53.8 | G36: =E36*F36 -> 9953 | H36: 1 | I36: 46090 | J36: 50.2 | K36: =E36*J36 -> 9287 | L36: =ROUND(J36*E36*0.1425%,0) -> 13 | M36: =ROUND(J36*E36*0.3%,0) -> 28 | N36: 0 | O36: =IF(I36="",E36*Y36,0) -> 0 | P36: =IF(I36="",R36-H36,(K36-H36-SUM(L36:N36)+R36-S36-T36)-G36)+(ROUND(R36*V36,0)-ROUND(R36*(1+V36),0)*W36) -> -16.47 | Q36: =IF(I36="",(O36-G36-(O36*0.1425%*0.65)-(O36*0.3%)-S36-T36),0) -> 0 | R36: 777 | U36: =(V36*50%)/(1+50%*V36) -> 0 | W36: 0.11 | X36: =(P36+Q36)/G36 -> -0.0016547775 | Y36: =VLOOKUP(C36,台股行情!A:D,4,FALSE) -> 64.35 | Z36: =VLOOKUP(C36,台股行情!A:E,5,FALSE) -> -2.2 | AA36: =IF(I36="",((TODAY()-A36)*G36)/365.24,((I36-A36)*G36)/365.24) -> 4496.3449 | AB36: 存股 | AC36: 美伊戰爭，憂心崩跌，認賠出場
A37: 45937 | C37: 770 | D37: =VLOOKUP(C37,台股行情!A:B,2,FALSE) -> 國泰北美科技 | E37: 181 | F37: 54.96 | G37: 9947 | H37: 1 | I37: 46090 | J37: 50.2 | K37: =E37*J37 -> 9086.2 | L37: =ROUND(J37*E37*0.1425%,0) -> 13 | M37: =ROUND(J37*E37*0.3%,0) -> 27 | N37: 0 | O37: =IF(I37="",E37*Y37,0) -> 0 | P37: =IF(I37="",R37-H37,(K37-H37-SUM(L37:N37)+R37-S37-T37)-G37)+(ROUND(R37*V37,0)-ROUND(R37*(1+V37),0)*W37) -> -225.2 | Q37: =IF(I37="",(O37-G37-(O37*0.1425%*0.65)-(O37*0.3%)-S37-T37),0) -> 0 | R37: 760.2 | U37: =(V37*50%)/(1+50%*V37) -> 0 | W37: 0.11 | X37: =(P37+Q37)/G37 -> -0.022639992 | Y37: =VLOOKUP(C37,台股行情!A:D,4,FALSE) -> 64.35 | Z37: =VLOOKUP(C37,台股行情!A:E,5,FALSE) -> -2.2 | AA37: =IF(I37="",((TODAY()-A37)*G37)/365.24,((I37-A37)*G37)/365.24) -> 4166.8246 | AB37: 存股 | AC37: 美伊戰爭，憂心崩跌，認賠出場
A38: 45945 | C38: 770 | D38: =VLOOKUP(C38,台股行情!A:B,2,FALSE) -> 國泰北美科技 | E38: 182 | F38: 54.88 | G38: 9988 | H38: 1 | I38: 46090 | J38: 50.2 | K38: =E38*J38 -> 9136.4 | L38: =ROUND(J38*E38*0.1425%,0) -> 13 | M38: =ROUND(J38*E38*0.3%,0) -> 27 | N38: 0 | O38: =IF(I38="",E38*Y38,0) -> 0 | P38: =IF(I38="",R38-H38,(K38-H38-SUM(L38:N38)+R38-S38-T38)-G38)+(ROUND(R38*V38,0)-ROUND(R38*(1+V38),0)*W38) -> -212.24 | Q38: =IF(I38="",(O38-G38-(O38*0.1425%*0.65)-(O38*0.3%)-S38-T38),0) -> 0 | R38: 764.4 | U38: =(V38*50%)/(1+50%*V38) -> 0 | W38: 0.11 | X38: =(P38+Q38)/G38 -> -0.021249499 | Y38: =VLOOKUP(C38,台股行情!A:D,4,FALSE) -> 64.35 | Z38: =VLOOKUP(C38,台股行情!A:E,5,FALSE) -> -2.2 | AA38: =IF(I38="",((TODAY()-A38)*G38)/365.24,((I38-A38)*G38)/365.24) -> 3965.2283 | AB38: 存股 | AC38: 美伊戰爭，憂心崩跌，認賠出場
A39: 45957 | C39: 770 | D39: =VLOOKUP(C39,台股行情!A:B,2,FALSE) -> 國泰北美科技 | E39: 174 | F39: 57.41 | G39: 9989 | H39: 1 | I39: 46090 | J39: 50.2 | K39: =E39*J39 -> 8734.8 | L39: =ROUND(J39*E39*0.1425%,0) -> 12 | M39: =ROUND(J39*E39*0.3%,0) -> 26 | N39: 0 | O39: =IF(I39="",E39*Y39,0) -> 0 | P39: =IF(I39="",R39-H39,(K39-H39-SUM(L39:N39)+R39-S39-T39)-G39)+(ROUND(R39*V39,0)-ROUND(R39*(1+V39),0)*W39) -> -642.81 | Q39: =IF(I39="",(O39-G39-(O39*0.1425%*0.65)-(O39*0.3%)-S39-T39),0) -> 0 | R39: 730.8 | U39: =(V39*50%)/(1+50%*V39) -> 0 | W39: 0.11 | X39: =(P39+Q39)/G39 -> -0.064351787 | Y39: =VLOOKUP(C39,台股行情!A:D,4,FALSE) -> 64.35 | Z39: =VLOOKUP(C39,台股行情!A:E,5,FALSE) -> -2.2 | AA39: =IF(I39="",((TODAY()-A39)*G39)/365.24,((I39-A39)*G39)/365.24) -> 3637.4357 | AB39: 存股 | AC39: 美伊戰爭，憂心崩跌，認賠出場
A40: 45966 | C40: 770 | D40: =VLOOKUP(C40,台股行情!A:B,2,FALSE) -> 國泰北美科技 | E40: 174 | F40: 56.6 | G40: 9961 | H40: 1 | I40: 46090 | J40: 50.2 | K40: =E40*J40 -> 8734.8 | L40: =ROUND(J40*E40*0.1425%,0) -> 12 | M40: =ROUND(J40*E40*0.3%,0) -> 26 | N40: 0 | O40: =IF(I40="",E40*Y40,0) -> 0 | P40: =IF(I40="",R40-H40,(K40-H40-SUM(L40:N40)+R40-S40-T40)-G40)+(ROUND(R40*V40,0)-ROUND(R40*(1+V40),0)*W40) -> -614.81 | Q40: =IF(I40="",(O40-G40-(O40*0.1425%*0.65)-(O40*0.3%)-S40-T40),0) -> 0 | R40: 730.8 | U40: =(V40*50%)/(1+50%*V40) -> 0 | W40: 0.11 | X40: =(P40+Q40)/G40 -> -0.061721715 | Y40: =VLOOKUP(C40,台股行情!A:D,4,FALSE) -> 64.35 | Z40: =VLOOKUP(C40,台股行情!A:E,5,FALSE) -> -2.2 | AA40: =IF(I40="",((TODAY()-A40)*G40)/365.24,((I40-A40)*G40)/365.24) -> 3381.7873 | AB40: 存股 | AC40: 美伊戰爭，憂心崩跌，認賠出場
A41: 45978 | C41: 770 | D41: =VLOOKUP(C41,台股行情!A:B,2,FALSE) -> 國泰北美科技 | E41: 176 | F41: 56.51 | G41: 9945 | H41: 1 | I41: 46090 | J41: 50.2 | K41: =E41*J41 -> 8835.2 | L41: =ROUND(J41*E41*0.1425%,0) -> 13 | M41: =ROUND(J41*E41*0.3%,0) -> 27 | N41: 0 | O41: =IF(I41="",E41*Y41,0) -> 0 | P41: =IF(I41="",R41-H41,(K41-H41-SUM(L41:N41)+R41-S41-T41)-G41)+(ROUND(R41*V41,0)-ROUND(R41*(1+V41),0)*W41) -> -492.89 | Q41: =IF(I41="",(O41-G41-(O41*0.1425%*0.65)-(O41*0.3%)-S41-T41),0) -> 0 | R41: 739.2 | U41: =(V41*50%)/(1+50%*V41) -> 0 | W41: 0.11 | X41: =(P41+Q41)/G41 -> -0.049561589 | Y41: =VLOOKUP(C41,台股行情!A:D,4,FALSE) -> 64.35 | Z41: =VLOOKUP(C41,台股行情!A:E,5,FALSE) -> -2.2 | AA41: =IF(I41="",((TODAY()-A41)*G41)/365.24,((I41-A41)*G41)/365.24) -> 3049.6112 | AB41: 存股 | AC41: 美伊戰爭，憂心崩跌，認賠出場
...

Sheet 24
A1: 買進日期 | B1: 種類 | C1: 股票代號 | D1: 股票名稱 | E1: 股數 | F1: 買進價 | G1: 成交金額 | H1: 手續費 | I1: 賣出日期 | J1: 賣出價 | K1: 成交金額 | L1: 手續費 | M1: 交易稅 | N1: 證所稅 | O1: 參考現值 | P1: 已實現損益 | Q1: 未實現損益 | R1: 除息 | S1: 手續費 | T1: 健保補充保費 | U1: 實質扣抵稅率 | V1: 扣抵稅率 | W1: 所得稅率 | X1: 投資報酬率 | Y1: 今日股價 | Z1: 漲跌 | AB1: 買進理由 | AC1: 賣出理由
A2: 45349 | C2: 3163 | D2: =VLOOKUP(C2,台股行情!A:B,2,FALSE) -> 波若威 | E2: 1000 | F2: 105.5 | G2: =E2*F2 -> 105500 | H2: 150 | I2: 45366 | J2: 106 | K2: =E2*J2 -> 106000 | L2: 151 | M2: 318 | N2: 0 | O2: =IF(I2="",E2*Y2,0) -> 0 | P2: =IF(I2="",R2-H2,(K2-H2-SUM(L2:N2)+R2-S2-T2)-G2)+(ROUND(R2*V2,0)-ROUND(R2*(1+V2),0)*W2) -> -119 | Q2: =IF(I2="",(O2-G2-(O2*0.1425%*0.65)-(O2*0.3%)-S2-T2),0) -> 0 | U2: =(V2*50%)/(1+50%*V2) -> 0 | W2: 0.11 | X2: =(P2+Q2)/G2 -> -0.0011279621 | Y2: =VLOOKUP(C2,台股行情!A:D,4,FALSE) -> 604 | Z2: =VLOOKUP(C2,台股行情!A:E,5,FALSE) -> -49 | AA2: =IF(I2="",((TODAY()-A2)*G2)/365.24,((I2-A2)*G2)/365.24) -> 4910.4698 | AB2: 阿水一式 | AC2: 破 20MA，停損
A3: 45359 | C3: 6176 | D3: =VLOOKUP(C3,台股行情!A:B,2,FALSE) -> 瑞儀 | E3: 1000 | F3: 168.5 | G3: =E3*F3 -> 168500 | H3: 240 | I3: 45366 | J3: 173 | K3: =E3*J3 -> 173000 | L3: 246 | M3: 519 | N3: 0 | O3: =IF(I3="",E3*Y3,0) -> 0 | P3: =IF(I3="",R3-H3,(K3-H3-SUM(L3:N3)+R3-S3-T3)-G3)+(ROUND(R3*V3,0)-ROUND(R3*(1+V3),0)*W3) -> 3495 | Q3: =IF(I3="",(O3-G3-(O3*0.1425%*0.65)-(O3*0.3%)-S3-T3),0) -> 0 | U3: =(V3*50%)/(1+50%*V3) -> 0 | W3: 0.11 | X3: =(P3+Q3)/G3 -> 0.02074184 | Y3: =VLOOKUP(C3,台股行情!A:D,4,FALSE) -> 91 | Z3: =VLOOKUP(C3,台股行情!A:E,5,FALSE) -> -0.7 | AA3: =IF(I3="",((TODAY()-A3)*G3)/365.24,((I3-A3)*G3)/365.24) -> 3229.3834 | AB3: 阿水一式 | AC3: 碰 20MA，獲利了結
A4: 45362 | C4: 3171 | D4: =VLOOKUP(C4,台股行情!A:B,2,FALSE) -> 炎洲流通 | E4: 1000 | F4: 31.95 | G4: =E4*F4 -> 31950 | H4: 45 | I4: 45380 | J4: 30.4 | K4: =E4*J4 -> 30400 | L4: 43 | M4: 91 | N4: 0 | O4: =IF(I4="",E4*Y4,0) -> 0 | P4: =IF(I4="",R4-H4,(K4-H4-SUM(L4:N4)+R4-S4-T4)-G4)+(ROUND(R4*V4,0)-ROUND(R4*(1+V4),0)*W4) -> -1729 | Q4: =IF(I4="",(O4-G4-(O4*0.1425%*0.65)-(O4*0.3%)-S4-T4),0) -> 0 | U4: =(V4*50%)/(1+50%*V4) -> 0 | W4: 0.11 | X4: =(P4+Q4)/G4 -> -0.054115806 | Y4: =VLOOKUP(C4,台股行情!A:D,4,FALSE) -> 57.8 | Z4: =VLOOKUP(C4,台股行情!A:E,5,FALSE) -> -0.7 | AA4: =IF(I4="",((TODAY()-A4)*G4)/365.24,((I4-A4)*G4)/365.24) -> 1574.5811 | AB4: 每月必漲股 | AC4: 月底出清 | AD4: 若在3/1買進23.95, 則為獲利
A5: 45359 | C5: 6596 | D5: =VLOOKUP(C5,台股行情!A:B,2,FALSE) -> 寬宏藝術 | E5: 1000 | F5: 60 | G5: =E5*F5 -> 60000 | H5: 85 | I5: 45393 | J5: 71 | K5: =E5*J5 -> 71000 | L5: 101 | M5: 213 | N5: 0 | O5: =IF(I5="",E5*Y5,0) -> 0 | P5: =IF(I5="",R5-H5,(K5-H5-SUM(L5:N5)+R5-S5-T5)-G5)+(ROUND(R5*V5,0)-ROUND(R5*(1+V5),0)*W5) -> 15308 | Q5: =IF(I5="",(O5-G5-(O5*0.1425%*0.65)-(O5*0.3%)-S5-T5),0) -> 0 | R5: 5300 | S5: 10 | U5: =(V5*50%)/(1+50%*V5) -> 0 | W5: 0.11 | X5: =(P5+Q5)/G5 -> 0.25513333 | Y5: =VLOOKUP(C5,台股行情!A:D,4,FALSE) -> 95.3 | Z5: =VLOOKUP(C5,台股行情!A:E,5,FALSE) -> 0 | AA5: =IF(I5="",((TODAY()-A5)*G5)/365.24,((I5-A5)*G5)/365.24) -> 5585.3685 | AB5: 阿水一式
A6: 45390 | C6: 6899 | D6: =VLOOKUP(C6,台股行情!A:B,2,FALSE) -> 創為精密 | E6: 1000 | F6: 50 | G6: =E6*F6 -> 50000 | H6: 50 | I6: 45393 | J6: 67.3 | K6: =E6*J6 -> 67300 | L6: 95 | M6: 201 | N6: 0 | O6: =IF(I6="",E6*Y6,0) -> 0 | P6: =IF(I6="",R6-H6,(K6-H6-SUM(L6:N6)+R6-S6-T6)-G6)+(ROUND(R6*V6,0)-ROUND(R6*(1+V6),0)*W6) -> 16954 | Q6: =IF(I6="",(O6-G6-(O6*0.1425%*0.65)-(O6*0.3%)-S6-T6),0) -> 0 | U6: =(V6*50%)/(1+50%*V6) -> 0 | W6: 0.11 | X6: =(P6+Q6)/G6 -> 0.33908 | Y6: =VLOOKUP(C6,台股行情!A:D,4,FALSE) -> 48.75 | Z6: =VLOOKUP(C6,台股行情!A:E,5,FALSE) -> -0.1 | AA6: =IF(I6="",((TODAY()-A6)*G6)/365.24,((I6-A6)*G6)/365.24) -> 410.68886 | AB6: 抽籤
A7: 45383 | C7: 1784 | D7: =VLOOKUP(C7,台股行情!A:B,2,FALSE) -> 訊聯 | E7: 1000 | F7: 62.8 | G7: =E7*F7 -> 62800 | H7: 89 | I7: 45418 | J7: 67 | K7: =E7*J7 -> 67000 | L7: 95 | M7: 201 | N7: 0 | O7: =IF(I7="",E7*Y7,0) -> 0 | P7: =IF(I7="",R7-H7,(K7-H7-SUM(L7:N7)+R7-S7-T7)-G7)+(ROUND(R7*V7,0)-ROUND(R7*(1+V7),0)*W7) -> 3815 | Q7: =IF(I7="",(O7-G7-(O7*0.1425%*0.65)-(O7*0.3%)-S7-T7),0) -> 0 | U7: =(V7*50%)/(1+50%*V7) -> 0 | W7: 0.11 | X7: =(P7+Q7)/G7 -> 0.060748408 | Y7: =VLOOKUP(C7,台股行情!A:D,4,FALSE) -> 56.3 | Z7: =VLOOKUP(C7,台股行情!A:E,5,FALSE) -> -1.5 | AA7: =IF(I7="",((TODAY()-A7)*G7)/365.24,((I7-A7)*G7)/365.24) -> 6017.9608 | AB7: 每月必漲股 | AC7: 月底出清
A8: 45383 | C8: 4175 | D8: =VLOOKUP(C8,台股行情!A:B,2,FALSE) -> 杏一 | E8: 1000 | F8: 79.4 | G8: =E8*F8 -> 79400 | H8: 113 | I8: 45418 | J8: 76.8 | K8: =E8*J8 -> 76800 | L8: 109 | M8: 230 | N8: 0 | O8: =IF(I8="",E8*Y8,0) -> 0 | P8: =IF(I8="",R8-H8,(K8-H8-SUM(L8:N8)+R8-S8-T8)-G8)+(ROUND(R8*V8,0)-ROUND(R8*(1+V8),0)*W8) -> -3052 | Q8: =IF(I8="",(O8-G8-(O8*0.1425%*0.65)-(O8*0.3%)-S8-T8),0) -> 0 | U8: =(V8*50%)/(1+50%*V8) -> 0 | W8: 0.11 | X8: =(P8+Q8)/G8 -> -0.038438287 | Y8: =VLOOKUP(C8,台股行情!A:D,4,FALSE) -> 50.9 | Z8: =VLOOKUP(C8,台股行情!A:E,5,FALSE) -> -0.1 | AA8: =IF(I8="",((TODAY()-A8)*G8)/365.24,((I8-A8)*G8)/365.24) -> 7608.6957 | AB8: 每月必漲股 | AC8: 月底出清
A9: 45383 | C9: 6263 | D9: =VLOOKUP(C9,台股行情!A:B,2,FALSE) -> 普萊德 | E9: 1000 | F9: 157 | G9: =E9*F9 -> 157000 | H9: 223 | I9: 45420 | J9: 159 | K9: =E9*J9 -> 159000 | L9: 226 | M9: 47 | N9: 0 | O9: =IF(I9="",E9*Y9,0) -> 0 | P9: =IF(I9="",R9-H9,(K9-H9-SUM(L9:N9)+R9-S9-T9)-G9)+(ROUND(R9*V9,0)-ROUND(R9*(1+V9),0)*W9) -> 1504 | Q9: =IF(I9="",(O9-G9-(O9*0.1425%*0.65)-(O9*0.3%)-S9-T9),0) -> 0 | U9: =(V9*50%)/(1+50%*V9) -> 0 | W9: 0.11 | X9: =(P9+Q9)/G9 -> 0.0095796178 | Y9: =VLOOKUP(C9,台股行情!A:D,4,FALSE) -> 173 | Z9: =VLOOKUP(C9,台股行情!A:E,5,FALSE) -> -4 | AA9: =IF(I9="",((TODAY()-A9)*G9)/365.24,((I9-A9)*G9)/365.24) -> 15904.611 | AB9: 每月必漲股 | AC9: 月底出清
A10: 45455 | C10: 4588 | D10: =VLOOKUP(C10,台股行情!A:B,2,FALSE) -> 玖鼎電力 | E10: 1000 | F10: 110.5 | G10: =E10*F10 -> 110500 | H10: 157 | I10: 45461 | J10: 115 | K10: =E10*J10 -> 115000 | L10: 163 | M10: 345 | N10: 0 | O10: =IF(I10="",E10*Y10,0) -> 0 | P10: =IF(I10="",R10-H10,(K10-H10-SUM(L10:N10)+R10-S10-T10)-G10)+(ROUND(R10*V10,0)-ROUND(R10*(1+V10),0)*W10) -> 3835 | Q10: =IF(I10="",(O10-G10-(O10*0.1425%*0.65)-(O10*0.3%)-S10-T10),0) -> 0 | U10: =(V10*50%)/(1+50%*V10) -> 0 | W10: 0.11 | X10: =(P10+Q10)/G10 -> 0.034705882 | Y10: =VLOOKUP(C10,台股行情!A:D,4,FALSE) -> 56.5 | Z10: =VLOOKUP(C10,台股行情!A:E,5,FALSE) -> -0.2 | AA10: =IF(I10="",((TODAY()-A10)*G10)/365.24,((I10-A10)*G10)/365.24) -> 1815.2448 | AB10: 阿水一式 | AC10: 大盤已是高點，破 5MA，獲利了結
A11: 45464 | C11: 6651 | D11: =VLOOKUP(C11,台股行情!A:B,2,FALSE) -> 全宇昕 | E11: 1000 | F11: 76.8 | G11: =E11*F11 -> 76800 | H11: 109 | I11: 45471 | J11: 72.5 | K11: =E11*J11 -> 72500 | L11: 103 | M11: 271 | N11: 0 | O11: =IF(I11="",E11*Y11,0) -> 0 | P11: =IF(I11="",R11-H11,(K11-H11-SUM(L11:N11)+R11-S11-T11)-G11)+(ROUND(R11*V11,0)-ROUND(R11*(1+V11),0)*W11) -> -1233 | Q11: =IF(I11="",(O11-G11-(O11*0.1425%*0.65)-(O11*0.3%)-S11-T11),0) -> 0 | R11: 4000 | S11: 10 | U11: =(V11*50%)/(1+50%*V11) -> 0 | W11: 0.11 | X11: =(P11+Q11)/G11 -> -0.016054688 | Y11: =VLOOKUP(C11,台股行情!A:D,4,FALSE) -> 141 | Z11: =VLOOKUP(C11,台股行情!A:E,5,FALSE) -> -3 | AA11: =IF(I11="",((TODAY()-A11)*G11)/365.24,((I11-A11)*G11)/365.24) -> 1471.9089 | AB11: 除權息 | AC11: 破 20MA，停損
A12: 45469 | C12: 1473 | D12: =VLOOKUP(C12,台股行情!A:B,2,FALSE) -> 台南 | E12: 1000 | F12: 48.75 | G12: =E12*F12 -> 48750 | H12: 69 | I12: 45474 | J12: 44.5 | K12: =E12*J12 -> 44500 | L12: 62 | M12: 132 | N12: 0 | O12: =IF(I12="",E12*Y12,0) -> 0 | P12: =IF(I12="",R12-H12,(K12-H12-SUM(L12:N12)+R12-S12-T12)-G12)+(ROUND(R12*V12,0)-ROUND(R12*(1+V12),0)*W12) -> -3455 | Q12: =IF(I12="",(O12-G12-(O12*0.1425%*0.65)-(O12*0.3%)-S12-T12),0) -> 0 | R12: 1200 | S12: 10 | U12: =(V12*50%)/(1+50%*V12) -> 0 | W12: 0.11 | X12: =(P12+Q12)/G12 -> -0.070871795 | Y12: =VLOOKUP(C12,台股行情!A:D,4,FALSE) -> 18.85 | Z12: =VLOOKUP(C12,台股行情!A:E,5,FALSE) -> -0.15 | AA12: =IF(I12="",((TODAY()-A12)*G12)/365.24,((I12-A12)*G12)/365.24) -> 667.3694 | AB12: 除權息 | AC12: 破 20MA，停損
